Workbook

Sheet Resource
A1: 年 | B1: 月份 | C1: 期間資料版本 | D1: 公司 | E1: 事業單位 | F1: 作業中心 | G1: 作業中心-第一階 | H1: 作業中心-第二階 | I1: 可控制/不可控制之資源 | J1: 成本類型 | K1: 停止分攤 | L1: 資源代碼 | M1: 資源-第一階 | N1: 金額 | O1: 資源動因 | P1: 動因簡述 | Q1: 資源動因值 | R1: (受)支援作業中心 | S1: 價值標的類型 | T1: 價值標的代碼 | U1: 資源動因費率
A2: 2018 | B2: 3 | C2: 201803 | D2: Kelly Group | E2: 公隆化學股份有限公司 | F2: NASL10:新事業開發部 | G2: NASL10:新事業開發部 | I2: 可控制之資源 | J2: 1.作業中心自用之資源 | K2: False | L2: R02 | M2: 差旅費用 | N2: 130000 | O2: (DirectAssigned) | P2: (直接歸屬)
A3: 2018 | B3: 3 | C3: 201803 | D3: Kelly Group | E3: 公隆化學股份有限公司 | F3: NASL11:製程化學課 | G3: NASL10:新事業開發部 | H3: NASL11:製程化學課 | I3: 可控制之資源 | J3: 1.作業中心自用之資源 | K3: True | L3: R02 | M3: 差旅費用 | N3: 40342 | O3: (DirectAssigned) | P3: (直接歸屬)
A4: 2018 | B4: 3 | C4: 201803 | D4: Kelly Group | E4: 公隆化學股份有限公司 | F4: NASL12:電子化學課 | G4: NASL10:新事業開發部 | H4: NASL12:電子化學課 | I4: 可控制之資源 | J4: 1.作業中心自用之資源 | K4: True | L4: R02 | M4: 差旅費用 | N4: 61118 | O4: (DirectAssigned) | P4: (直接歸屬)
A5: 2018 | B5: 3 | C5: 201803 | D5: Kelly Group | E5: 公隆化學股份有限公司 | F5: NASL11:製程化學課 | G5: NASL10:新事業開發部 | H5: NASL11:製程化學課 | I5: 不可控制之資源 | J5: 5.支援作業中心(SSU)分攤之資源 | K5: True | L5: R01 | M5: 薪資費用 | N5: 218161 | O5: (ByDriverValue) | P5: (設定比率) | Q5: 1 | R5: NATC11:應用技術課 | U5: 218161
A6: 2018 | B6: 3 | C6: 201803 | D6: Kelly Group | E6: 公隆化學股份有限公司 | F6: NASL11:製程化學課 | G6: NASL10:新事業開發部 | H6: NASL11:製程化學課 | I6: 不可控制之資源 | J6: 4.管理作業中心分攤之資源 | K6: True | L6: R02 | M6: 差旅費用 | N6: 104000 | O6: (ByDriverValue) | P6: (設定比率) | Q6: 0.8 | R6: NASL10:新事業開發部 | U6: 130000
A7: 2018 | B7: 3 | C7: 201803 | D7: Kelly Group | E7: 公隆化學股份有限公司 | F7: NASL12:電子化學課 | G7: NASL10:新事業開發部 | H7: NASL12:電子化學課 | I7: 不可控制之資源 | J7: 4.管理作業中心分攤之資源 | K7: True | L7: R02 | M7: 差旅費用 | N7: 26000 | O7: (ByDriverValue) | P7: (設定比率) | Q7: 0.2 | R7: NASL10:新事業開發部 | U7: 130000
A8: 2018 | B8: 3 | C8: 201803 | D8: Kelly Group | E8: 公隆化學股份有限公司 | F8: NASL11:製程化學課 | G8: NASL10:新事業開發部 | H8: NASL11:製程化學課 | I8: 可控制之資源 | J8: 1.作業中心自用之資源 | K8: True | L8: R01 | M8: 薪資費用 | N8: 71367 | O8: (DirectAssigned) | P8: (直接歸屬)
A9: 2018 | B9: 3 | C9: 201803 | D9: Kelly Group | E9: 公隆化學股份有限公司 | F9: NATC11:應用技術課 | G9: NASL10:新事業開發部 | H9: NATC11:應用技術課 | I9: 可控制之資源 | J9: 1.作業中心自用之資源 | K9: False | L9: R01 | M9: 薪資費用 | N9: 218161 | O9: (DirectAssigned) | P9: (直接歸屬)
A10: 2018 | B10: 3 | C10: 201803 | D10: Kelly Group | E10: 公隆化學股份有限公司 | F10: NASL12:電子化學課 | G10: NASL10:新事業開發部 | H10: NASL12:電子化學課 | I10: 可控制之資源 | J10: 1.作業中心自用之資源 | K10: True | L10: R01 | M10: 薪資費用 | N10: 125323 | O10: (DirectAssigned) | P10: (直接歸屬)
A11: 2018 | B11: 3 | C11: 201803 | D11: Kelly Group | E11: 公隆化學股份有限公司 | F11: NASL11:製程化學課 | G11: NASL10:新事業開發部 | H11: NASL11:製程化學課 | I11: 可控制之資源 | J11: 2.價值標的使用之資源 | K11: True | L11: R03 | M11: 交際費用 | N11: 300 | O11: (DirectAssigned) | P11: (直接歸屬) | S11: CustomerProject | T11: CPCRM00696:專案-健達生物
A12: 2018 | B12: 3 | C12: 201803 | D12: Kelly Group | E12: 公隆化學股份有限公司 | F12: NASL11:製程化學課 | G12: NASL10:新事業開發部 | H12: NASL11:製程化學課 | I12: 可控制之資源 | J12: 2.價值標的使用之資源 | K12: True | L12: R04 | M12: 樣品費用 | N12: 6350 | O12: (DirectAssigned) | P12: (直接歸屬) | S12: CustomerProject | T12: CPCRM00696:專案-健達生物
A13: 2018 | B13: 3 | C13: 201803 | D13: Kelly Group | E13: 公隆化學股份有限公司 | F13: NASL11:製程化學課 | G13: NASL10:新事業開發部 | H13: NASL11:製程化學課 | I13: 可控制之資源 | J13: 2.價值標的使用之資源 | K13: True | L13: R04 | M13: 樣品費用 | N13: 3372 | O13: (DirectAssigned) | P13: (直接歸屬) | S13: CustomerProject | T13: CPCRM00911:專案-台灣鉅邁
A14: 2018 | B14: 3 | C14: 201803 | D14: Kelly Group | E14: 公隆化學股份有限公司 | F14: NASL12:電子化學課 | G14: NASL10:新事業開發部 | H14: NASL12:電子化學課 | I14: 可控制之資源 | J14: 2.價值標的使用之資源 | K14: True | L14: R03 | M14: 交際費用 | N14: 1035 | O14: (DirectAssigned) | P14: (直接歸屬) | S14: CustomerProject | T14: CPCRM05498:專案-興勤電子
A15: 2018 | B15: 3 | C15: 201803 | D15: Kelly Group | E15: 公隆化學股份有限公司 | F15: NASL12:電子化學課 | G15: NASL10:新事業開發部 | H15: NASL12:電子化學課 | I15: 可控制之資源 | J15: 2.價值標的使用之資源 | K15: True | L15: R03 | M15: 交際費用 | N15: 3526 | O15: (DirectAssigned) | P15: (直接歸屬) | S15: CustomerProject | T15: CPCRM10848:專案-華新科技
A16: 2018 | B16: 3 | C16: 201803 | D16: Kelly Group | E16: 公隆化學股份有限公司 | F16: NASL12:電子化學課 | G16: NASL10:新事業開發部 | H16: NASL12:電子化學課 | I16: 可控制之資源 | J16: 2.價值標的使用之資源 | K16: True | L16: R03 | M16: 交際費用 | N16: 8493 | O16: (DirectAssigned) | P16: (直接歸屬) | S16: CustomerProject | T16: CPCRM11533:專案-國巨楠梓
A17: 2018 | B17: 3 | C17: 201803 | D17: Kelly Group | E17: 公隆化學股份有限公司 | F17: NASL11:製程化學課 | G17: NASL10:新事業開發部 | H17: NASL11:製程化學課 | I17: 可控制之資源 | J17: 2.價值標的使用之資源 | K17: True | L17: R05 | M17: 其他費用 | N17: 24210 | O17: (DirectAssigned) | P17: (直接歸屬) | S17: CustomerProject | T17: CPunknow:專案-未分析顧客
A18: 2018 | B18: 3 | C18: 201803 | D18: Kelly Group | E18: 公隆化學股份有限公司 | F18: NASL10:新事業開發部 | G18: NASL10:新事業開發部 | I18: 可控制之資源 | J18: 2.價值標的使用之資源 | K18: True | L18: R05 | M18: 其他費用 | N18: 3092 | O18: (DirectAssigned) | P18: (直接歸屬) | S18: CustomerProject | T18: CPunknow:專案-未分析顧客
A19: 2018 | B19: 3 | C19: 201803 | D19: Kelly Group | E19: 公隆化學股份有限公司 | F19: NASL12:電子化學課 | G19: NASL10:新事業開發部 | H19: NASL12:電子化學課 | I19: 可控制之資源 | J19: 2.價值標的使用之資源 | K19: True | L19: R05 | M19: 其他費用 | N19: 16648 | O19: (DirectAssigned) | P19: (直接歸屬) | S19: CustomerProject | T19: CPunknow:專案-未分析顧客
A20: 2018 | B20: 4 | C20: 201804 | D20: Kelly Group | E20: 公隆化學股份有限公司 | F20: NASL11:製程化學課 | G20: NASL10:新事業開發部 | H20: NASL11:製程化學課 | I20: 可控制之資源 | J20: 2.價值標的使用之資源 | K20: True | L20: R05 | M20: 其他費用 | N20: 3500 | O20: (DirectAssigned) | P20: (直接歸屬) | S20: CustomerProject | T20: CPCRM00400:專案-東隆五金
A21: 2018 | B21: 4 | C21: 201804 | D21: Kelly Group | E21: 公隆化學股份有限公司 | F21: NASL11:製程化學課 | G21: NASL10:新事業開發部 | H21: NASL11:製程化學課 | I21: 可控制之資源 | J21: 2.價值標的使用之資源 | K21: True | L21: R05 | M21: 其他費用 | N21: 1500 | O21: (DirectAssigned) | P21: (直接歸屬) | S21: CustomerProject | T21: CP華震科技:專案-華震科技
A22: 2018 | B22: 4 | C22: 201804 | D22: Kelly Group | E22: 公隆化學股份有限公司 | F22: NASL12:電子化學課 | G22: NASL10:新事業開發部 | H22: NASL12:電子化學課 | I22: 可控制之資源 | J22: 2.價值標的使用之資源 | K22: True | L22: R05 | M22: 其他費用 | N22: 1600 | O22: (DirectAssigned) | P22: (直接歸屬) | S22: CustomerProject | T22: CPCRM10848:專案-華新科技
A23: 2018 | B23: 4 | C23: 201804 | D23: Kelly Group | E23: 公隆化學股份有限公司 | F23: NASL12:電子化學課 | G23: NASL10:新事業開發部 | H23: NASL12:電子化學課 | I23: 可控制之資源 | J23: 2.價值標的使用之資源 | K23: True | L23: R03 | M23: 交際費用 | N23: 535 | O23: (DirectAssigned) | P23: (直接歸屬) | S23: CustomerProject | T23: CPCRM17381:專案-桃園-愛賽克
A24: 2018 | B24: 4 | C24: 201804 | D24: Kelly Group | E24: 公隆化學股份有限公司 | F24: NASL12:電子化學課 | G24: NASL10:新事業開發部 | H24: NASL12:電子化學課 | I24: 可控制之資源 | J24: 2.價值標的使用之資源 | K24: True | L24: R05 | M24: 其他費用 | N24: 3500 | O24: (DirectAssigned) | P24: (直接歸屬) | S24: CustomerProject | T24: CPCRM19822:專案-友達
A25: 2018 | B25: 4 | C25: 201804 | D25: Kelly Group | E25: 公隆化學股份有限公司 | F25: NASL12:電子化學課 | G25: NASL10:新事業開發部 | H25: NASL12:電子化學課 | I25: 可控制之資源 | J25: 2.價值標的使用之資源 | K25: True | L25: R05 | M25: 其他費用 | N25: 5409 | O25: (DirectAssigned) | P25: (直接歸屬) | S25: CustomerProject | T25: CPunknow:專案-未分析顧客
A26: 2018 | B26: 4 | C26: 201804 | D26: Kelly Group | E26: 公隆化學股份有限公司 | F26: NASL10:新事業開發部 | G26: NASL10:新事業開發部 | I26: 可控制之資源 | J26: 2.價值標的使用之資源 | K26: True | L26: R05 | M26: 其他費用 | N26: 3991 | O26: (DirectAssigned) | P26: (直接歸屬) | S26: CustomerProject | T26: CPunknow:專案-未分析顧客
A27: 2018 | B27: 4 | C27: 201804 | D27: Kelly Group | E27: 公隆化學股份有限公司 | F27: NASL11:製程化學課 | G27: NASL10:新事業開發部 | H27: NASL11:製程化學課 | I27: 可控制之資源 | J27: 2.價值標的使用之資源 | K27: True | L27: R05 | M27: 其他費用 | N27: 11664 | O27: (DirectAssigned) | P27: (直接歸屬) | S27: CustomerProject | T27: CPunknow:專案-未分析顧客
A28: 2018 | B28: 4 | C28: 201804 | D28: Kelly Group | E28: 公隆化學股份有限公司 | F28: NASL11:製程化學課 | G28: NASL10:新事業開發部 | H28: NASL11:製程化學課 | I28: 可控制之資源 | J28: 2.價值標的使用之資源 | K28: True | L28: R05 | M28: 其他費用 | N28: 1467 | O28: (DirectAssigned) | P28: (直接歸屬) | S28: CustomerProject | T28: CPEMERSON:專案-EMERSON
A29: 2018 | B29: 4 | C29: 201804 | D29: Kelly Group | E29: 公隆化學股份有限公司 | F29: NASL11:製程化學課 | G29: NASL10:新事業開發部 | H29: NASL11:製程化學課 | I29: 可控制之資源 | J29: 1.作業中心自用之資源 | K29: True | L29: R01 | M29: 薪資費用 | N29: 106463 | O29: (DirectAssigned) | P29: (直接歸屬)
A30: 2018 | B30: 4 | C30: 201804 | D30: Kelly Group | E30: 公隆化學股份有限公司 | F30: NATC11:應用技術課 | G30: NASL10:新事業開發部 | H30: NATC11:應用技術課 | I30: 可控制之資源 | J30: 1.作業中心自用之資源 | K30: False | L30: R01 | M30: 薪資費用 | N30: 268081 | O30: (DirectAssigned) | P30: (直接歸屬)
A31: 2018 | B31: 4 | C31: 201804 | D31: Kelly Group | E31: 公隆化學股份有限公司 | F31: NASL12:電子化學課 | G31: NASL10:新事業開發部 | H31: NASL12:電子化學課 | I31: 可控制之資源 | J31: 1.作業中心自用之資源 | K31: True | L31: R01 | M31: 薪資費用 | N31: 135850 | O31: (DirectAssigned) | P31: (直接歸屬)
A32: 2018 | B32: 4 | C32: 201804 | D32: Kelly Group | E32: 公隆化學股份有限公司 | F32: NASL11:製程化學課 | G32: NASL10:新事業開發部 | H32: NASL11:製程化學課 | I32: 不可控制之資源 | J32: 5.支援作業中心(SSU)分攤之資源 | K32: True | L32: R01 | M32: 薪資費用 | N32: 268081 | O32: (ByDriverValue) | P32: (設定比率) | Q32: 1 | R32: NATC11:應用技術課 | U32: 268081
A33: 2018 | B33: 4 | C33: 201804 | D33: Kelly Group | E33: 公隆化學股份有限公司 | F33: NASL11:製程化學課 | G33: NASL10:新事業開發部 | H33: NASL11:製程化學課 | I33: 不可控制之資源 | J33: 4.管理作業中心分攤之資源 | K33: True | L33: R02 | M33: 差旅費用 | N33: 104000 | O33: (ByDriverValue) | P33: (設定比率) | Q33: 0.8 | R33: NASL10:新事業開發部 | U33: 130000
A34: 2018 | B34: 4 | C34: 201804 | D34: Kelly Group | E34: 公隆化學股份有限公司 | F34: NASL12:電子化學課 | G34: NASL10:新事業開發部 | H34: NASL12:電子化學課 | I34: 不可控制之資源 | J34: 4.管理作業中心分攤之資源 | K34: True | L34: R02 | M34: 差旅費用 | N34: 26000 | O34: (ByDriverValue) | P34: (設定比率) | Q34: 0.2 | R34: NASL10:新事業開發部 | U34: 130000
A35: 2018 | B35: 4 | C35: 201804 | D35: Kelly Group | E35: 公隆化學股份有限公司 | F35: NASL10:新事業開發部 | G35: NASL10:新事業開發部 | I35: 可控制之資源 | J35: 1.作業中心自用之資源 | K35: False | L35: R02 | M35: 差旅費用 | N35: 130000 | O35: (DirectAssigned) | P35: (直接歸屬)
A36: 2018 | B36: 4 | C36: 201804 | D36: Kelly Group | E36: 公隆化學股份有限公司 | F36: NASL11:製程化學課 | G36: NASL10:新事業開發部 | H36: NASL11:製程化學課 | I36: 可控制之資源 | J36: 1.作業中心自用之資源 | K36: True | L36: R02 | M36: 差旅費用 | N36: 171828 | O36: (DirectAssigned) | P36: (直接歸屬)
A37: 2018 | B37: 4 | C37: 201804 | D37: Kelly Group | E37: 公隆化學股份有限公司 | F37: NASL12:電子化學課 | G37: NASL10:新事業開發部 | H37: NASL12:電子化學課 | I37: 可控制之資源 | J37: 1.作業中心自用之資源 | K37: True | L37: R02 | M37: 差旅費用 | N37: 39822 | O37: (DirectAssigned) | P37: (直接歸屬)
A38: 2018 | B38: 5 | C38: 201805 | D38: Kelly Group | E38: 公隆化學股份有限公司 | F38: NASL10:新事業開發部 | G38: NASL10:新事業開發部 | I38: 可控制之資源 | J38: 1.作業中心自用之資源 | K38: False | L38: R02 | M38: 差旅費用 | N38: 130000 | O38: (DirectAssigned) | P38: (直接歸屬)
A39: 2018 | B39: 5 | C39: 201805 | D39: Kelly Group | E39: 公隆化學股份有限公司 | F39: NASL11:製程化學課 | G39: NASL10:新事業開發部 | H39: NASL11:製程化學課 | I39: 可控制之資源 | J39: 1.作業中心自用之資源 | K39: True | L39: R02 | M39: 差旅費用 | N39: 86278 | O39: (DirectAssigned) | P39: (直接歸屬)
A40: 2018 | B40: 5 | C40: 201805 | D40: Kelly Group | E40: 公隆化學股份有限公司 | F40: NASL12:電子化學課 | G40: NASL10:新事業開發部 | H40: NASL12:電子化學課 | I40: 不可控制之資源 | J40: 4.管理作業中心分攤之資源 | K40: True | L40: R02 | M40: 差旅費用 | N40: 26000 | O40: (ByDriverValue) | P40: (設定比率) | Q40: 0.2 | R40: NASL10:新事業開發部 | U40: 130000
...

Sheet 可控不可控
A1: 停止分攤 | B1: True
A3: 加總 - 金額 | C3: 月份
A4: 作業中心 | B4: 可控制/不可控制之資源 | C4: 3 | D4: 4 | E4: 5 | F4: Grand Total
A5: NASL10:新事業開發部 | B5: 可控制之資源 | C5: 3092 | D5: 3991 | E5: 2506 | F5: 9589
A6: NASL11:製程化學課 | B6: 不可控制之資源 | C6: 322161 | D6: 372081 | E6: 343124 | F6: 1037366
B7: 可控制之資源 | C7: 145941 | D7: 296422 | E7: 202416 | F7: 644779
A8: NASL12:電子化學課 | B8: 不可控制之資源 | C8: 26000 | D8: 26000 | E8: 26000 | F8: 78000
B9: 可控制之資源 | C9: 216143 | D9: 186716 | E9: 154984 | F9: 557843
A10: Grand Total | C10: 713337 | D10: 885210 | E10: 729030 | F10: 2327577

Sheet 可控不可控 (2)
A1: 停止分攤 | B1: True
A3: 加總 - 金額 | D3: 月份
A4: 作業中心 | B4: 可控制/不可控制之資源 | C4: 資源-第一階 | D4: 3 | E4: 4 | F4: 5 | G4: Grand Total
A5: NASL10:新事業開發部 | B5: 可控制之資源 | C5: 其他費用 | D5: 3092 | E5: 3991 | F5: 2506 | G5: 9589
A6: NASL11:製程化學課 | B6: 不可控制之資源 | D6: 322161 | E6: 372081 | F6: 343124 | G6: 1037366
B7: 可控制之資源 | C7: 交際費用 | D7: 300 | G7: 300
C8: 其他費用 | D8: 24210 | E8: 18131 | F8: 13474 | G8: 55815
C9: 差旅費用 | D9: 40342 | E9: 171828 | F9: 86278 | G9: 298448
C10: 樣品費用 | D10: 9722 | F10: 7236 | G10: 16958
C11: 薪資費用 | D11: 71367 | E11: 106463 | F11: 95428 | G11: 273258
A12: NASL12:電子化學課 | B12: 不可控制之資源 | D12: 26000 | E12: 26000 | F12: 26000 | G12: 78000
B13: 可控制之資源 | C13: 交際費用 | D13: 13054 | E13: 535 | G13: 13589
C14: 其他費用 | D14: 16648 | E14: 10509 | F14: 18177 | G14: 45334
C15: 差旅費用 | D15: 61118 | E15: 39822 | G15: 100940
C16: 薪資費用 | D16: 125323 | E16: 135850 | F16: 136807 | G16: 397980
A17: Grand Total | D17: 713337 | E17: 885210 | F17: 729030 | G17: 2327577

Sheet ActivityCenter+ActivityModel
A1: 年 | B1: 月份 | C1: 期間資料版本 | D1: 公司 | E1: 事業單位 | F1: 作業中心-第一階 | G1: 作業中心-第二階 | H1: 成本類型 | I1: 金額 | J1: 作業中心動因費率 | K1: 作業中心動因值 | L1: 作業-第一階 | M1: 作業-第二階 | N1: 附加價值屬性 | O1: 顧客服務屬性
A2: 2018 | B2: 3 | C2: 201803 | D2: Kelly Group | E2: 公隆化學股份有限公司 | F2: NASL10:新事業開發部 | G2: NASL11:製程化學課 | H2: N. Cap. Rate*N. Cap. Hour | I2: 173548 | J2: 39.299819 | K2: 4416 | L2: N01:取得顧客作業
A3: 2018 | B3: 3 | C3: 201803 | D3: Kelly Group | E3: 公隆化學股份有限公司 | F3: NASL10:新事業開發部 | G3: NASL12:電子化學課 | H3: N. Cap. Rate*N. Cap. Hour | I3: 106220.5 | J3: 9.6214221 | K3: 11040 | L3: N01:取得顧客作業
A4: 2018 | B4: 3 | C4: 201803 | D4: Kelly Group | E4: 公隆化學股份有限公司 | F4: NASL10:新事業開發部 | G4: NASL11:製程化學課 | H4: N. Cap. Rate*N. Cap. Hour | I4: 86774 | J4: 39.299819 | K4: 2208 | L4: N02:維持顧客作業
A5: 2018 | B5: 3 | C5: 201803 | D5: Kelly Group | E5: 公隆化學股份有限公司 | F5: NASL10:新事業開發部 | G5: NASL12:電子化學課 | H5: N. Cap. Rate*N. Cap. Hour | I5: 33990.56 | J5: 9.6214221 | K5: 3532.8 | L5: N02:維持顧客作業
A6: 2018 | B6: 3 | C6: 201803 | D6: Kelly Group | E6: 公隆化學股份有限公司 | F6: NASL10:新事業開發部 | G6: NASL11:製程化學課 | H6: N. Cap. Rate*N. Cap. Hour | I6: 130161 | J6: 39.299819 | K6: 3312 | L6: N03:售後服務作業
A7: 2018 | B7: 3 | C7: 201803 | D7: Kelly Group | E7: 公隆化學股份有限公司 | F7: NASL10:新事業開發部 | G7: NASL12:電子化學課 | H7: N. Cap. Rate*N. Cap. Hour | I7: 33990.56 | J7: 9.6214221 | K7: 3532.8 | L7: N03:售後服務作業
A8: 2018 | B8: 3 | C8: 201803 | D8: Kelly Group | E8: 公隆化學股份有限公司 | F8: NASL10:新事業開發部 | G8: NASL11:製程化學課 | H8: N. Cap. Rate*N. Cap. Hour | I8: 43387 | J8: 39.299819 | K8: 1104 | L8: N04:其他
A9: 2018 | B9: 3 | C9: 201803 | D9: Kelly Group | E9: 公隆化學股份有限公司 | F9: NASL10:新事業開發部 | G9: NASL12:電子化學課 | H9: N. Cap. Rate*N. Cap. Hour | I9: 38239.38 | J9: 9.6214221 | K9: 3974.4 | L9: N04:其他
A10: 2018 | B10: 3 | C10: 201803 | D10: Kelly Group | E10: 公隆化學股份有限公司 | F10: NASL10:新事業開發部 | G10: NASL11:製程化學課 | H10: A. Cap. Rate*A. Cap. Hour | I10: 8174.3623 | J10: 39.299819 | K10: 208 | L10: N02:維持顧客作業 | M10: A01:關係維護 | N10: 有附加價值 | O10: 維持成本
A11: 2018 | B11: 3 | C11: 201803 | D11: Kelly Group | E11: 公隆化學股份有限公司 | F11: NASL10:新事業開發部 | G11: NASL11:製程化學課 | H11: N. Cap. Rate*A. Cap. Hour | I11: 8174.3623 | J11: 39.299819 | K11: 208 | L11: N02:維持顧客作業 | M11: A01:關係維護 | N11: 有附加價值 | O11: 維持成本
A12: 2018 | B12: 3 | C12: 201803 | D12: Kelly Group | E12: 公隆化學股份有限公司 | F12: NASL10:新事業開發部 | G12: NASL12:電子化學課 | H12: A. Cap. Rate*A. Cap. Hour | I12: 5328.7876 | J12: 9.6014191 | K12: 555 | L12: N02:維持顧客作業 | M12: A01:關係維護 | N12: 有附加價值 | O12: 維持成本
A13: 2018 | B13: 3 | C13: 201803 | D13: Kelly Group | E13: 公隆化學股份有限公司 | F13: NASL10:新事業開發部 | G13: NASL12:電子化學課 | H13: N. Cap. Rate*A. Cap. Hour | I13: 5339.8893 | J13: 9.6214221 | K13: 555 | L13: N02:維持顧客作業 | M13: A01:關係維護 | N13: 有附加價值 | O13: 維持成本
A14: 2018 | B14: 3 | C14: 201803 | D14: Kelly Group | E14: 公隆化學股份有限公司 | F14: NASL10:新事業開發部 | G14: NASL11:製程化學課 | H14: A. Cap. Rate*A. Cap. Hour | I14: 8174.3623 | J14: 39.299819 | K14: 208 | L14: N01:取得顧客作業 | M14: A02:市場動態 | N14: 有附加價值 | O14: 取得成本
A15: 2018 | B15: 3 | C15: 201803 | D15: Kelly Group | E15: 公隆化學股份有限公司 | F15: NASL10:新事業開發部 | G15: NASL11:製程化學課 | H15: N. Cap. Rate*A. Cap. Hour | I15: 8174.3623 | J15: 39.299819 | K15: 208 | L15: N01:取得顧客作業 | M15: A02:市場動態 | N15: 有附加價值 | O15: 取得成本
A16: 2018 | B16: 3 | C16: 201803 | D16: Kelly Group | E16: 公隆化學股份有限公司 | F16: NASL10:新事業開發部 | G16: NASL12:電子化學課 | H16: A. Cap. Rate*A. Cap. Hour | I16: 8425.2453 | J16: 9.6014191 | K16: 877.5 | L16: N01:取得顧客作業 | M16: A02:市場動態 | N16: 有附加價值 | O16: 取得成本
A17: 2018 | B17: 3 | C17: 201803 | D17: Kelly Group | E17: 公隆化學股份有限公司 | F17: NASL10:新事業開發部 | G17: NASL12:電子化學課 | H17: N. Cap. Rate*A. Cap. Hour | I17: 8442.7979 | J17: 9.6214221 | K17: 877.5 | L17: N01:取得顧客作業 | M17: A02:市場動態 | N17: 有附加價值 | O17: 取得成本
A18: 2018 | B18: 3 | C18: 201803 | D18: Kelly Group | E18: 公隆化學股份有限公司 | F18: NASL10:新事業開發部 | G18: NASL11:製程化學課 | H18: N. Cap. Rate*A. Cap. Hour | I18: 0 | J18: 39.299819 | K18: 0 | L18: N01:取得顧客作業 | M18: A03:爭取新專案 | N18: 有附加價值 | O18: 取得成本
A19: 2018 | B19: 3 | C19: 201803 | D19: Kelly Group | E19: 公隆化學股份有限公司 | F19: NASL10:新事業開發部 | G19: NASL12:電子化學課 | H19: A. Cap. Rate*A. Cap. Hour | I19: 39101.779 | J19: 9.6014191 | K19: 4072.5 | L19: N01:取得顧客作業 | M19: A03:爭取新專案 | N19: 有附加價值 | O19: 取得成本
A20: 2018 | B20: 3 | C20: 201803 | D20: Kelly Group | E20: 公隆化學股份有限公司 | F20: NASL10:新事業開發部 | G20: NASL12:電子化學課 | H20: N. Cap. Rate*A. Cap. Hour | I20: 39183.242 | J20: 9.6214221 | K20: 4072.5 | L20: N01:取得顧客作業 | M20: A03:爭取新專案 | N20: 有附加價值 | O20: 取得成本
A21: 2018 | B21: 3 | C21: 201803 | D21: Kelly Group | E21: 公隆化學股份有限公司 | F21: NASL10:新事業開發部 | G21: NASL11:製程化學課 | H21: A. Cap. Rate*A. Cap. Hour | I21: 0 | J21: 39.299819 | K21: 0 | L21: N01:取得顧客作業 | M21: A04:專案追蹤 | N21: 有附加價值 | O21: 取得成本
... A134: 2018 | B134: 4 | C134: 201804 | D134: Kelly Group | E134: 公隆化學股份有限公司 | F134: NASL10:新事業開發部 | G134: NASL12:電子化學課 | H134: N. Cap. Rate*A. Cap. Hour | I134: 17149.759 | J134: 12.731818 | K134: 1347 | L134: N02:維持顧客作業 | M134: A01:關係維護 | N134: 有附加價值 | O134: 維持成本
A135: 2018 | B135: 4 | C135: 201804 | D135: Kelly Group | E135: 公隆化學股份有限公司 | F135: NASL10:新事業開發部 | G135: NASL11:製程化學課 | H135: N. Cap. Rate*N. Cap. Hour | I135: 65037.2 | J135: 75.274537 | K135: 864 | L135: N04:其他
A136: 2018 | B136: 4 | C136: 201804 | D136: Kelly Group | E136: 公隆化學股份有限公司 | F136: NASL10:新事業開發部 | G136: NASL12:電子化學課 | H136: N. Cap. Rate*N. Cap. Hour | I136: 36300.96 | J136: 12.731818 | K136: 2851.2 | L136: N04:其他
A137: 2018 | B137: 4 | C137: 201804 | D137: Kelly Group | E137: 公隆化學股份有限公司 | F137: NASL10:新事業開發部 | G137: NASL11:製程化學課 | H137: N. Cap. Rate*N. Cap. Hour | I137: 195111.6 | J137: 75.274537 | K137: 2592 | L137: N03:售後服務作業
A138: 2018 | B138: 4 | C138: 201804 | D138: Kelly Group | E138: 公隆化學股份有限公司 | F138: NASL10:新事業開發部 | G138: NASL12:電子化學課 | H138: N. Cap. Rate*N. Cap. Hour | I138: 32267.52 | J138: 12.731818 | K138: 2534.4 | L138: N03:售後服務作業
A139: 2018 | B139: 4 | C139: 201804 | D139: Kelly Group | E139: 公隆化學股份有限公司 | F139: NASL10:新事業開發部 | G139: NASL11:製程化學課 | H139: N. Cap. Rate*N. Cap. Hour | I139: 130074.4 | J139: 75.274537 | K139: 1728 | L139: N02:維持顧客作業
A140: 2018 | B140: 4 | C140: 201804 | D140: Kelly Group | E140: 公隆化學股份有限公司 | F140: NASL10:新事業開發部 | G140: NASL12:電子化學課 | H140: N. Cap. Rate*N. Cap. Hour | I140: 32267.52 | J140: 12.731818 | K140: 2534.4 | L140: N02:維持顧客作業
A141: 2018 | B141: 4 | C141: 201804 | D141: Kelly Group | E141: 公隆化學股份有限公司 | F141: NASL10:新事業開發部 | G141: NASL11:製程化學課 | H141: N. Cap. Rate*N. Cap. Hour | I141: 260148.8 | J141: 75.274537 | K141: 3456 | L141: N01:取得顧客作業
A142: 2018 | B142: 4 | C142: 201804 | D142: Kelly Group | E142: 公隆化學股份有限公司 | F142: NASL10:新事業開發部 | G142: NASL12:電子化學課 | H142: N. Cap. Rate*N. Cap. Hour | I142: 100836 | J142: 12.731818 | K142: 7920 | L142: N01:取得顧客作業
A143: 2018 | B143: 5 | C143: 201805 | D143: Kelly Group | E143: 公隆化學股份有限公司 | F143: NASL10:新事業開發部 | G143: NASL11:製程化學課 | H143: N. Cap. Rate*N. Cap. Hour | I143: 209932 | J143: 49.699811 | K143: 4224 | L143: N01:取得顧客作業
A144: 2018 | B144: 5 | C144: 201805 | D144: Kelly Group | E144: 公隆化學股份有限公司 | F144: NASL10:新事業開發部 | G144: NASL12:電子化學課 | H144: N. Cap. Rate*N. Cap. Hour | I144: 81403.5 | J144: 8.2727134 | K144: 9840 | L144: N01:取得顧客作業
A145: 2018 | B145: 5 | C145: 201805 | D145: Kelly Group | E145: 公隆化學股份有限公司 | F145: NASL10:新事業開發部 | G145: NASL11:製程化學課 | H145: N. Cap. Rate*N. Cap. Hour | I145: 104966 | J145: 49.699811 | K145: 2112 | L145: N02:維持顧客作業
A146: 2018 | B146: 5 | C146: 201805 | D146: Kelly Group | E146: 公隆化學股份有限公司 | F146: NASL10:新事業開發部 | G146: NASL12:電子化學課 | H146: N. Cap. Rate*N. Cap. Hour | I146: 26049.12 | J146: 8.2727134 | K146: 3148.8 | L146: N02:維持顧客作業
... A150: 2018 | B150: 5 | C150: 201805 | D150: Kelly Group | E150: 公隆化學股份有限公司 | F150: NASL10:新事業開發部 | G150: NASL12:電子化學課 | H150: N. Cap. Rate*N. Cap. Hour | I150: 29305.26 | J150: 8.2727134 | K150: 3542.4 | L150: N04:其他
A151: 2018 | B151: 5 | C151: 201805 | D151: Kelly Group | E151: 公隆化學股份有限公司 | F151: NASL10:新事業開發部 | G151: NASL11:製程化學課 | H151: A. Cap. Rate*A. Cap. Hour | I151: 38964.652 | J151: 49.699811 | K151: 784 | L151: N02:維持顧客作業 | M151: A01:關係維護 | N151: 有附加價值 | O151: 維持成本
A152: 2018 | B152: 5 | C152: 201805 | D152: Kelly Group | E152: 公隆化學股份有限公司 | F152: NASL10:新事業開發部 | G152: NASL11:製程化學課 | H152: N. Cap. Rate*A. Cap. Hour | I152: 38964.652 | J152: 49.699811 | K152: 784 | L152: N02:維持顧客作業 | M152: A01:關係維護 | N152: 有附加價值 | O152: 維持成本
A153: 2018 | B153: 5 | C153: 201805 | D153: Kelly Group | E153: 公隆化學股份有限公司 | F153: NASL10:新事業開發部 | G153: NASL12:電子化學課 | H153: N. Cap. Rate*A. Cap. Hour | I153: 0 | J153: 8.2727134 | K153: 0 | L153: N02:維持顧客作業 | M153: A01:關係維護 | N153: 有附加價值 | O153: 維持成本
A154: 2018 | B154: 5 | C154: 201805 | D154: Kelly Group | E154: 公隆化學股份有限公司 | F154: NASL10:新事業開發部 | G154: NASL11:製程化學課 | H154: N. Cap. Rate*A. Cap. Hour | I154: 0 | J154: 49.699811 | K154: 0 | L154: N01:取得顧客作業 | M154: A02:市場動態 | N154: 有附加價值 | O154: 取得成本
A155: 2018 | B155: 5 | C155: 201805 | D155: Kelly Group | E155: 公隆化學股份有限公司 | F155: NASL10:新事業開發部 | G155: NASL12:電子化學課 | H155: A. Cap. Rate*A. Cap. Hour | I155: 3970.9024 | J155: 8.2727134 | K155: 480 | L155: N01:取得顧客作業 | M155: A02:市場動態 | N155: 有附加價值 | O155: 取得成本
...

Sheet 單位實際作業成本
A2: 成本類型 | B2: A. Cap. Rate*A. Cap. Hour
A4: 加總 - 作業中心動因費率 | B4: 欄標籤
A5: 列標籤 | B5: 3 | C5: 4 | D5: 5 | E5: 總計
A6: NASL11:製程化學課 | B6: 314.39855 | C6: 526.92176 | D6: 447.2983 | E6: 1288.6186 | G6: 3月 | H6: 4月 | I6: 5月
A7: A01:關係維護 | B7: 39.299819 | D7: 49.699811 | E7: 88.999629 | G7: 8種作業 | H7: 7種作業 | I7: 9種作業
A8: A02:市場動態 | B8: 39.299819 | E8: 39.299819 | G8: 市場動態專案追蹤
A9: A04:專案追蹤 | B9: 39.299819 | E9: 39.299819
A10: A05:拜訪新客戶 | B10: 39.299819 | C10: 75.274537 | D10: 49.699811 | E10: 164.27417
A11: A06:小批量試產 | D11: 49.699811 | E11: 49.699811
A12: A07:推薦新產品 | B12: 39.299819 | E12: 39.299819
A13: A08:新線(產品)追蹤 | D13: 49.699811 | E13: 49.699811
A14: A09:偕同技術服務 | B14: 39.299819 | C14: 75.274537 | D14: 49.699811 | E14: 164.27417
A15: A11:取樣分析 | B15: 39.299819 | C15: 75.274537 | D15: 49.699811 | E15: 164.27417
A16: A16:試樣 | D16: 49.699811 | E16: 49.699811
A17: A17:製程改善 | D17: 49.699811 | E17: 49.699811
A18: A18:Kelly內部事項 | B18: 39.299819 | C18: 75.274537 | D18: 49.699811 | E18: 164.27417
A19: A19:目標客戶拜訪 | C19: 75.274537 | E19: 75.274537
A20: A20:合作夥伴拜訪 | C20: 75.274537 | E20: 75.274537
A21: A22:帳款收回 | C21: 75.274537 | E21: 75.274537
A22: NASL12:電子化學課 | B22: 115.21703 | C22: 127.31818 | D22: 49.63628 | E22: 292.17149
A23: A01:關係維護 | B23: 9.6014191 | C23: 12.731818 | E23: 22.333237
A24: A02:市場動態 | B24: 9.6014191 | C24: 12.731818 | D24: 8.2727134 | E24: 30.605951
A25: A03:爭取新專案 | B25: 9.6014191 | C25: 12.731818 | D25: 8.2727134 | E25: 30.605951
A26: A04:專案追蹤 | B26: 9.6014191 | C26: 12.731818 | D26: 8.2727134 | E26: 30.605951
A27: A05:拜訪新客戶 | B27: 9.6014191 | C27: 12.731818 | D27: 8.2727134 | E27: 30.605951
A28: A07:推薦新產品 | B28: 9.6014191 | C28: 12.731818 | E28: 22.333237
A29: A08:新線(產品)追蹤 | B29: 9.6014191 | E29: 9.6014191
A30: A09:偕同技術服務 | B30: 9.6014191 | E30: 9.6014191
A31: A10:偕同原廠拜訪 | B31: 9.6014191 | E31: 9.6014191
A32: A11:取樣分析 | B32: 9.6014191 | E32: 9.6014191
A33: A12:客服諮詢 | B33: 9.6014191 | E33: 9.6014191
A34: A13:客訴處理 | C34: 12.731818 | E34: 12.731818
A35: A18:Kelly內部事項 | B35: 9.6014191 | C35: 12.731818 | D35: 8.2727134 | E35: 30.605951
A36: A19:目標客戶拜訪 | C36: 12.731818 | D36: 8.2727134 | E36: 21.004532
A37: A22:帳款收回 | C37: 12.731818 | E37: 12.731818
A38: 總計 | B38: 429.61558 | C38: 654.23994 | D38: 496.93458 | E38: 1580.7901

Sheet 附加價值
A2: 成本類型 | B2: A. Cap. Rate*A. Cap. Hour
A4: 加總 - 金額 | B4: Column Labels
A5: Row Labels | B5: 3 | C5: 4 | D5: 5 | E5: Grand Total
A6: 有附加價值 | B6: 646311 | C6: 848377.24 | D6: 687637 | E6: 2182325.2
A7: 無附加價值 | C7: 3666.7636 | E7: 3666.7636
A8: A13:客訴處理 | C8: 3666.7636 | E8: 3666.7636
A9: Grand Total | B9: 646311 | C9: 852044 | D9: 687637 | E9: 2185992

Sheet 顧客服務屬性
A1: 成本類型 | B1: A. Cap. Rate*A. Cap. Hour
A3: 加總 - 金額 | B3: Column Labels
A4: Row Labels | B4: 3 | C4: 4 | D4: 5 | E4: Grand Total
A5: NA | B5: 309323.22 | C5: 469410.75 | D5: 389544.87 | E5: 1168278.8
A6: 取得成本 | B6: 301468.58 | C6: 361014.62 | D6: 253262.9 | E6: 915746.1
A7: 服務成本 | B7: 5885.6699 | C7: 4468.8682 | D7: 5864.5777 | E7: 16219.116
A8: A08:新線(產品)追蹤 | B8: 1276.9887 | D8: 2882.589 | E8: 4159.5778
A9: A12:客服諮詢 | B9: 4608.6812 | E9: 4608.6812
A10: A13:客訴處理 | C10: 3666.7636 | E10: 3666.7636
A11: A17:製程改善 | D11: 2981.9886 | E11: 2981.9886
A12: A22:帳款收回 | C12: 802.10455 | E12: 802.10455
A13: 維持成本 | B13: 29633.534 | C13: 17149.759 | D13: 38964.652 | E13: 85747.945
A14: Grand Total | B14: 646311 | C14: 852044 | D14: 687637 | E14: 2185992

Sheet ActivityCenter
A1: 年 | B1: 月份 | C1: 期間資料版本 | D1: 公司 | E1: 事業單位 | F1: 作業中心 | G1: 作業中心-第一階 | H1: 作業中心-第二階 | I1: 人/機時 | J1: 作業-第一階 | K1: 正常產能費率 | L1: 實際產能費率 | M1: 正常產能(時間) | N1: 實際產能(時間) | O1: 正常產能金額(N*N) | P1: 實際產能金額(A*A) | Q1: 剩餘(超用)產能時間
A2: 2018 | B2: 3 | C2: 201803 | D2: Kelly Group | E2: 公隆化學股份有限公司 | F2: NASL11:製程化學課 | G2: NASL10:新事業開發部 | H2: NASL11:製程化學課 | I2: MAN POWER | J2: N04:其他 | K2: 39.299819 | L2: 39.299819 | M2: 1104 | N2: 5760 | O2: 43387 | P2: 226366.96 | Q2: -4656
A3: 2018 | B3: 3 | C3: 201803 | D3: Kelly Group | E3: 公隆化學股份有限公司 | F3: NASL11:製程化學課 | G3: NASL10:新事業開發部 | H3: NASL11:製程化學課 | I3: MAN POWER | J3: N03:售後服務作業 | K3: 39.299819 | L3: 39.299819 | M3: 3312 | N3: 0 | O3: 130161 | P3: 0 | Q3: 3312
A4: 2018 | B4: 3 | C4: 201803 | D4: Kelly Group | E4: 公隆化學股份有限公司 | F4: NASL11:製程化學課 | G4: NASL10:新事業開發部 | H4: NASL11:製程化學課 | I4: MAN POWER | J4: N01:取得顧客作業 | K4: 39.299819 | L4: 39.299819 | M4: 4416 | N4: 5072 | O4: 173548 | P4: 199328.68 | Q4: -656
A5: 2018 | B5: 3 | C5: 201803 | D5: Kelly Group | E5: 公隆化學股份有限公司 | F5: NASL11:製程化學課 | G5: NASL10:新事業開發部 | H5: NASL11:製程化學課 | I5: MAN POWER | J5: N02:維持顧客作業 | K5: 39.299819 | L5: 39.299819 | M5: 2208 | N5: 208 | O5: 86774 | P5: 8174.3623 | Q5: 2000
A6: 2018 | B6: 3 | C6: 201803 | D6: Kelly Group | E6: 公隆化學股份有限公司 | F6: NASL12:電子化學課 | G6: NASL10:新事業開發部 | H6: NASL12:電子化學課 | I6: MAN POWER | J6: N02:維持顧客作業 | K6: 9.6214221 | L6: 9.6014191 | M6: 3532.8 | N6: 2235 | O6: 33990.56 | P6: 21459.172 | Q6: 1297.8
A7: 2018 | B7: 3 | C7: 201803 | D7: Kelly Group | E7: 公隆化學股份有限公司 | F7: NASL12:電子化學課 | G7: NASL10:新事業開發部 | H7: NASL12:電子化學課 | I7: MAN POWER | J7: N04:其他 | K7: 9.6214221 | L7: 9.6014191 | M7: 3974.4 | N7: 8640 | O7: 38239.38 | P7: 82956.261 | Q7: -4665.6
A8: 2018 | B8: 3 | C8: 201803 | D8: Kelly Group | E8: 公隆化學股份有限公司 | F8: NASL12:電子化學課 | G8: NASL10:新事業開發部 | H8: NASL12:電子化學課 | I8: MAN POWER | J8: N01:取得顧客作業 | K8: 9.6214221 | L8: 9.6014191 | M8: 11040 | N8: 10638 | O8: 106220.5 | P8: 102139.9 | Q8: 402
A9: 2018 | B9: 3 | C9: 201803 | D9: Kelly Group | E9: 公隆化學股份有限公司 | F9: NASL12:電子化學課 | G9: NASL10:新事業開發部 | H9: NASL12:電子化學課 | I9: MAN POWER | J9: N03:售後服務作業 | K9: 9.6214221 | L9: 9.6014191 | M9: 3532.8 | N9: 613 | O9: 33990.56 | P9: 5885.6699 | Q9: 2919.8
A10: 2018 | B10: 4 | C10: 201804 | D10: Kelly Group | E10: 公隆化學股份有限公司 | F10: NASL11:製程化學課 | G10: NASL10:新事業開發部 | H10: NASL11:製程化學課 | I10: MAN POWER | J10: N04:其他 | K10: 75.274537 | L10: 75.274537 | M10: 864 | N10: 4937 | O10: 65037.2 | P10: 371630.39 | Q10: -4073
A11: 2018 | B11: 4 | C11: 201804 | D11: Kelly Group | E11: 公隆化學股份有限公司 | F11: NASL11:製程化學課 | G11: NASL10:新事業開發部 | H11: NASL11:製程化學課 | I11: MAN POWER | J11: N03:售後服務作業 | K11: 75.274537 | L11: 75.274537 | M11: 2592 | N11: 0 | O11: 195111.6 | P11: 0 | Q11: 2592
A12: 2018 | B12: 4 | C12: 201804 | D12: Kelly Group | E12: 公隆化學股份有限公司 | F12: NASL11:製程化學課 | G12: NASL10:新事業開發部 | H12: NASL11:製程化學課 | I12: MAN POWER | J12: N02:維持顧客作業 | K12: 75.274537 | L12: 75.274537 | M12: 1728 | N12: 0 | O12: 130074.4 | P12: 0 | Q12: 1728
A13: 2018 | B13: 4 | C13: 201804 | D13: Kelly Group | E13: 公隆化學股份有限公司 | F13: NASL11:製程化學課 | G13: NASL10:新事業開發部 | H13: NASL11:製程化學課 | I13: MAN POWER | J13: N01:取得顧客作業 | K13: 75.274537 | L13: 75.274537 | M13: 3456 | N13: 3703 | O13: 260148.8 | P13: 278741.61 | Q13: -247
... A25: 2018 | B25: 5 | C25: 201805 | D25: Kelly Group | E25: 公隆化學股份有限公司 | F25: NASL12:電子化學課 | G25: NASL10:新事業開發部 | H25: NASL12:電子化學課 | I25: MAN POWER | J25: N04:其他 | K25: 8.2727134 | L25: 8.2727134 | M25: 3542.4 | N25: 9600 | O25: 29305.26 | P25: 79418.049 | Q25: -6057.6

Sheet 超用剩餘
B3: 欄標籤
B4: 3 | E4: 4 | H4: 5 | K4: 加總 - 正常產能(時間) 的加總 | L4: 加總 - 實際產能(時間) 的加總 | M4: 加總 - 剩餘(超用)產能時間 的加總
A5: 列標籤 | B5: 加總 - 正常產能(時間) | C5: 加總 - 實際產能(時間) | D5: 加總 - 剩餘(超用)產能時間 | E5: 加總 - 正常產能(時間) | F5: 加總 - 實際產能(時間) | G5: 加總 - 剩餘(超用)產能時間 | H5: 加總 - 正常產能(時間) | I5: 加總 - 實際產能(時間) | J5: 加總 - 剩餘(超用)產能時間
A6: NASL11:製程化學課 | B6: 11040 | C6: 11040 | D6: 0 | E6: 8640 | F6: 8640 | G6: 0 | H6: 10560 | I6: 10560 | J6: 0 | K6: 30240 | L6: 30240 | M6: 0
A7: NASL12:電子化學課 | B7: 22080 | C7: 22126 | D7: -46 | E7: 15840 | F7: 15840 | G7: 0 | H7: 19680 | I7: 19680 | J7: 0 | K7: 57600 | L7: 57646 | M7: -46
A8: 總計 | B8: 33120 | C8: 33166 | D8: -46 | E8: 24480 | F8: 24480 | G8: 0 | H8: 30240 | I8: 30240 | J8: 0 | K8: 87840 | L8: 87886 | M8: -46

Sheet ActivityDriver
A1: 年 | B1: 月份 | C1: 期間資料版本 | D1: 公司 | E1: 事業單位 | F1: 作業中心 | G1: 實際產能費率成本 | H1: 正常產能費率成本 | I1: 作業-第一階 | J1: 作業-第二階 | K1: 作業動因 | L1: 作業動因值 | M1: 價值標的類型 | N1: 價值標的
A2: 2018 | B2: 3 | C2: 201803 | D2: Kelly Group | E2: 公隆化學股份有限公司 | F2: NASL12:電子化學課 | G2: 4608.6812 | H2: 4618.2826 | I2: N01:取得顧客作業 | J2: A03:爭取新專案 | K2: 拜訪時間 | L2: 480 | M2: CustomerProject:顧客專案 | N2: CPCRM12107:專案-達興
A3: 2018 | B3: 3 | C3: 201803 | D3: Kelly Group | E3: 公隆化學股份有限公司 | F3: NASL12:電子化學課 | G3: 1843.4725 | H3: 1847.313 | I3: N01:取得顧客作業 | J3: A03:爭取新專案 | K3: 拜訪時間 | L3: 192 | M3: CustomerProject:顧客專案 | N3: CPCRM19560:專案-山鶯欣興電子
A4: 2018 | B4: 3 | C4: 201803 | D4: Kelly Group | E4: 公隆化學股份有限公司 | F4: NASL12:電子化學課 | G4: 2064.3051 | H4: 2068.6058 | I4: N01:取得顧客作業 | J4: A03:爭取新專案 | K4: 拜訪時間 | L4: 215 | M4: CustomerProject:顧客專案 | N4: CPCRM19560:專案-山鶯欣興電子
A5: 2018 | B5: 3 | C5: 201803 | D5: Kelly Group | E5: 公隆化學股份有限公司 | F5: NASL12:電子化學課 | G5: 2736.4045 | H5: 2742.1053 | I5: N01:取得顧客作業 | J5: A03:爭取新專案 | K5: 拜訪時間 | L5: 285 | M5: CustomerProject:顧客專案 | N5: CPCRM20039:專案-樹林台電研究所
A6: 2018 | B6: 3 | C6: 201803 | D6: Kelly Group | E6: 公隆化學股份有限公司 | F6: NASL12:電子化學課 | G6: 4464.6599 | H6: 4473.9613 | I6: N01:取得顧客作業 | J6: A03:爭取新專案 | K6: 拜訪時間 | L6: 465 | M6: CustomerProject:顧客專案 | N6: CPCRM20254:專案-台灣奈晶
A7: 2018 | B7: 3 | C7: 201803 | D7: Kelly Group | E7: 公隆化學股份有限公司 | F7: NASL12:電子化學課 | G7: 3072.4541 | H7: 3078.8551 | I7: N01:取得顧客作業 | J7: A03:爭取新專案 | K7: 拜訪時間 | L7: 320 | M7: CustomerProject:顧客專案 | N7: CPCRM08397:專案-奇美實業
A8: 2018 | B8: 3 | C8: 201803 | D8: Kelly Group | E8: 公隆化學股份有限公司 | F8: NASL12:電子化學課 | G8: 2304.3406 | H8: 2309.1413 | I8: N01:取得顧客作業 | J8: A03:爭取新專案 | K8: 拜訪時間 | L8: 240 | M8: CustomerProject:顧客專案 | N8: CPCRM11452:專案-佳邦
A9: 2018 | B9: 3 | C9: 201803 | D9: Kelly Group | E9: 公隆化學股份有限公司 | F9: NASL12:電子化學課 | G9: 1315.3944 | H9: 1318.1348 | I9: N01:取得顧客作業 | J9: A03:爭取新專案 | K9: 拜訪時間 | L9: 137 | M9: CustomerProject:顧客專案 | N9: CPCRM17041:專案-新竹-錸德
A10: 2018 | B10: 3 | C10: 201803 | D10: Kelly Group | E10: 公隆化學股份有限公司 | F10: NASL12:電子化學課 | G10: 772.91424 | H10: 774.52448 | I10: N01:取得顧客作業 | J10: A03:爭取新專案 | K10: 拜訪時間 | L10: 80.5 | M10: CustomerProject:顧客專案 | N10: CPCRM17041:專案-新竹-錸德
A11: 2018 | B11: 3 | C11: 201803 | D11: Kelly Group | E11: 公隆化學股份有限公司 | F11: NASL12:電子化學課 | G11: 921.73624 | H11: 923.65652 | I11: N01:取得顧客作業 | J11: A03:爭取新專案 | K11: 拜訪時間 | L11: 96 | M11: CustomerProject:顧客專案 | N11: CP永光二廠:專案-永光二廠
A12: 2018 | B12: 3 | C12: 201803 | D12: Kelly Group | E12: 公隆化學股份有限公司 | F12: NASL12:電子化學課 | G12: 1843.4725 | H12: 1847.313 | I12: N01:取得顧客作業 | J12: A03:爭取新專案 | K12: 拜訪時間 | L12: 192 | M12: CustomerProject:顧客專案 | N12: CPCRM05175:專案-永光三廠
A13: 2018 | B13: 3 | C13: 201803 | D13: Kelly Group | E13: 公隆化學股份有限公司 | F13: NASL12:電子化學課 | G13: 1536.2271 | H13: 1539.4275 | I13: N01:取得顧客作業 | J13: A03:爭取新專案 | K13: 拜訪時間 | L13: 160 | M13: CustomerProject:顧客專案 | N13: CPCRM08460:專案-台虹科技
... A244: 2018 | B244: 5 | C244: 201805 | D244: Kelly Group | E244: 公隆化學股份有限公司 | F244: NASL11:製程化學課 | G244: 23855.909 | H244: 23855.909 | I244: N01:取得顧客作業 | J244: A16:試樣 | K244: 拜訪時間 | L244: 480 | M244: CustomerProject:顧客專案 | N244: CPCRM01101:專案-興展企業

Sheet 專案作業時間
A3: 加總 - 作業動因值 | B3: 欄標籤
A4: 列標籤 | B4: 3 | C4: 4 | D4: 5 | E4: 總計
A5: NASL11:製程化學課 | B5: 11040 | C5: 8640 | D5: 10560 | E5: 30240
A6: CP other cus:專案-other customer | B6: 5760 | C6: 4800 | D6: 6240 | E6: 16800
A7: CPCRM00550:專案-瑞興發 | B7: 48 | D7: 58 | E7: 106
A8: CPCRM00783:專案-亞洲漢威 | B8: 58 | E8: 58
A9: CPCRM00937:專案-大勤化成 | B9: 480 | E9: 480
A10: CPCRM01037:專案-華邦電 | B10: 226 | C10: 15 | E10: 241
A11: CPCRM01042:專案-欣銓科技 | B11: 136 | D11: 161 | E11: 297
A12: CPCRM01046:專案-華泰電子 | C12: 55 | D12: 146 | E12: 201
A13: CPCRM01049:專案-台星科 | B13: 145 | E13: 145
A14: CPCRM01052:專案-福懋科技 | B14: 137 | D14: 480 | E14: 617
A15: CPCRM01053:專案-渼豐表面處理 | C15: 101 | E15: 101
A16: CPCRM01073:專案-榮聰精密 | D16: 60 | E16: 60
A17: CPCRM01090:專案-台弟工業 | B17: 67 | E17: 67
A18: CPCRM01091:專案-群浤科技 | B18: 231 | E18: 231
A19: CPCRM01093:專案-巨品表面 | B19: 64 | E19: 64
A20: CPCRM01094:專案-旭德科技 | B20: 438 | C20: 265 | E20: 703
A21: CPCRM01095:專案-崇越石英製造廠 | B21: 215 | C21: 111 | E21: 326
A22: CPCRM01096:專案-南豐工業 | B22: 139 | E22: 139
A23: CPCRM01097:專案-矽格 | B23: 452 | E23: 452
A24: CPCRM01101:專案-興展企業 | B24: 123 | C24: 136 | D24: 908 | E24: 1167
A25: CPCRM01102:專案-欣旻工業 | B25: 131 | E25: 131
A26: CPCRM01103:專案-璟德電子 | B26: 135 | E26: 135
A27: CPCRM01105:專案-萬能科大 | B27: 416 | E27: 416
A28: CPCRM01109:專案-伍德邁 | D28: 367 | E28: 367
A29: CPCRM01111:專案-辛耘企業-二廠 | B29: 126 | D29: 79 | E29: 205
A30: CPCRM01117:專案-正修科大 | B30: 245 | E30: 245
A31: CPCRM01118:專案-捷暘 | B31: 480 | E31: 480
A32: CPCRM01121:專案-大發金屬 | C32: 171 | D32: 69 | E32: 240
A33: CPCRM01122:專案-玉美-生物科技 | C33: 155 | E33: 155
A34: CPCRM01123:專案-洗旺國際 | C34: 82 | E34: 82
A35: CPCRM01124:專案-日月展金屬 | C35: 72 | E35: 72
A36: CPCRM01125:專案-昌旺汽材 | C36: 98 | D36: 114 | E36: 212
A37: CPCRM01126:專案-彰陽工業 | C37: 70 | E37: 70
A38: CPCRM01127:專案-杰昌金屬 | C38: 157 | E38: 157
A39: CPCRM01128:專案-哈伯精密 | C39: 100 | E39: 100
A40: CPCRM01129:專案-雷電光能 | C40: 416 | D40: 316 | E40: 732
A41: CPCRM01130:專案-普聯國際 | C41: 137 | D41: 472 | E41: 609
A42: CPCRM01132:專案-台灣京濱化 | C42: 155 | E42: 155
...

Sheet PartStock
A1: 年 | B1: 月份 | C1: 期間資料版本 | D1: 公司 | E1: 事業單位 | F1: 價值標的類型 | G1: 料號 | H1: 類型 | I1: 數量 | J1: 金額
A2: 2018 | B2: 3 | C2: 201803 | D2: Kelly Group | E2: 公隆化學股份有限公司 | F2: 原物料 | G2: 61000017 | H2: 進料入庫 | I2: 300 | J2: 25265
A3: 2018 | B3: 3 | C3: 201803 | D3: Kelly Group | E3: 公隆化學股份有限公司 | F3: 原物料 | G3: 61000027 | H3: 進料入庫 | I3: 150 | J3: 5830
A4: 2018 | B4: 3 | C4: 201803 | D4: Kelly Group | E4: 公隆化學股份有限公司 | F4: 原物料 | G4: 61000028 | H4: 進料入庫 | I4: 480 | J4: 15966
A5: 2018 | B5: 3 | C5: 201803 | D5: Kelly Group | E5: 公隆化學股份有限公司 | F5: 原物料 | G5: 71000576 | H5: 進料入庫 | I5: 20 | J5: 2637
A6: 2018 | B6: 3 | C6: 201803 | D6: Kelly Group | E6: 公隆化學股份有限公司 | F6: 原物料 | G6: 74000063 | H6: 進料入庫 | I6: 20 | J6: 4592
A7: 2018 | B7: 3 | C7: 201803 | D7: Kelly Group | E7: 公隆化學股份有限公司 | F7: 原物料 | G7: 74000071 | H7: 進料入庫 | I7: 60 | J7: 7262
A8: 2018 | B8: 3 | C8: 201803 | D8: Kelly Group | E8: 公隆化學股份有限公司 | F8: 原物料 | G8: 74000158 | H8: 進料入庫 | I8: 428 | J8: 44091
A9: 2018 | B9: 3 | C9: 201803 | D9: Kelly Group | E9: 公隆化學股份有限公司 | F9: 原物料 | G9: 74000162 | H9: 進料入庫 | I9: 1000 | J9: 71469
A10: 2018 | B10: 3 | C10: 201803 | D10: Kelly Group | E10: 公隆化學股份有限公司 | F10: 原物料 | G10: 74000193 | H10: 進料入庫 | I10: 415.6 | J10: 33664
A11: 2018 | B11: 3 | C11: 201803 | D11: Kelly Group | E11: 公隆化學股份有限公司 | F11: 原物料 | G11: 74000242 | H11: 進料入庫 | I11: 36 | J11: 13292
A12: 2018 | B12: 3 | C12: 201803 | D12: Kelly Group | E12: 公隆化學股份有限公司 | F12: 原物料 | G12: 74000245 | H12: 進料入庫 | I12: 1250 | J12: 190000
A13: 2018 | B13: 3 | C13: 201803 | D13: Kelly Group | E13: 公隆化學股份有限公司 | F13: 原物料 | G13: 74000252 | H13: 進料入庫 | I13: 90 | J13: 27815
... A159: 2018 | B159: 5 | C159: 201805 | D159: Kelly Group | E159: 公隆化學股份有限公司 | F159: 產品 | G159: 88100060 | H159: 訂單出貨 | I159: -5 | J159: -60449

Sheet 存貨
A3: 加總 - 數量 | B3: 欄標籤
A4: 列標籤 | B4: 訂單出貨 | C4: 進料入庫 | D4: 總計
A5: 61000017 | B5: -1720 | C5: 1720 | D5: 0
A6: 61000027 | B6: -960 | C6: 960 | D6: 0
A7: 61000028 | B7: -960 | C7: 960 | D7: 0
A8: 71000576 | B8: -60 | C8: 60 | D8: 0
A9: 72000019 | B9: -80 | C9: 80 | D9: 0
A10: 72000045 | B10: -19.7 | C10: 19.7 | D10: 0
A11: 72100012 | B11: -160 | C11: 160 | D11: 0
A12: 72100014 | B12: -280 | C12: 280 | D12: 0
A13: 74000063 | B13: -20 | C13: 20 | D13: 0
A14: 74000071 | B14: -80 | C14: 80 | D14: 0
A15: 74000150 | B15: -40 | C15: 40 | D15: 0
A16: 74000158 | B16: -722 | C16: 722 | D16: 0
... A51: 總計 | B51: -18037.9 | C51: 18037.9 | D51: 0

Sheet Project
A1: 年 | B1: 月份 | C1: 期間資料版本 | D1: 公司 | E1: 事業單位 | F1: 專案代碼 | G1: 專案名稱 | H1: 價值標的類型 | I1: 類型 | J1: 作業中心 | K1: 資源/作業 | L1: 代碼 | M1: 金額 | N1: 實際產能(分鐘) | O1: 產品 | P1: 數量 | Q1: 業務工程師
A2: 2018 | B2: 3 | C2: 201803 | D2: Kelly Group | E2: 公隆化學股份有限公司 | F2: CPunknow | G2: 專案-未分析顧客 | H2: CustomerProject | I2: 成本累積 | J2: NASL10:新事業開發部 | K2: Resource | L2: R05:其他費用 | M2: 3092
A3: 2018 | B3: 3 | C3: 201803 | D3: Kelly Group | E3: 公隆化學股份有限公司 | F3: CPCRM00696 | G3: 專案-健達生物 | H3: CustomerProject | I3: 成本累積 | J3: NASL11:製程化學課 | K3: Resource | L3: R03:交際費用 | M3: 300 | Q3: Vincent
A4: 2018 | B4: 3 | C4: 201803 | D4: Kelly Group | E4: 公隆化學股份有限公司 | F4: CPCRM00696 | G4: 專案-健達生物 | H4: CustomerProject | I4: 成本累積 | J4: NASL11:製程化學課 | K4: Resource | L4: R04:樣品費 | M4: 6350 | Q4: Vincent
A5: 2018 | B5: 3 | C5: 201803 | D5: Kelly Group | E5: 公隆化學股份有限公司 | F5: CPCRM00911 | G5: 專案-台灣鉅邁 | H5: CustomerProject | I5: 成本累積 | J5: NASL11:製程化學課 | K5: Resource | L5: R04:樣品費 | M5: 3372 | Q5: Vincent
A6: 2018 | B6: 3 | C6: 201803 | D6: Kelly Group | E6: 公隆化學股份有限公司 | F6: CPunknow | G6: 專案-未分析顧客 | H6: CustomerProject | I6: 成本累積 | J6: NASL11:製程化學課 | K6: Resource | L6: R05:其他費用 | M6: 24210
A7: 2018 | B7: 3 | C7: 201803 | D7: Kelly Group | E7: 公隆化學股份有限公司 | F7: CPCRM05498 | G7: 專案-興勤電子 | H7: CustomerProject | I7: 成本累積 | J7: NASL12:電子化學課 | K7: Resource | L7: R03:交際費用 | M7: 1035 | Q7: Chris
A8: 2018 | B8: 3 | C8: 201803 | D8: Kelly Group | E8: 公隆化學股份有限公司 | F8: CPCRM10848 | G8: 專案-華新科技 | H8: CustomerProject | I8: 成本累積 | J8: NASL12:電子化學課 | K8: Resource | L8: R03:交際費用 | M8: 3526 | Q8: Chris
A9: 2018 | B9: 3 | C9: 201803 | D9: Kelly Group | E9: 公隆化學股份有限公司 | F9: CPCRM11533 | G9: 專案-國巨楠梓 | H9: CustomerProject | I9: 成本累積 | J9: NASL12:電子化學課 | K9: Resource | L9: R03:交際費用 | M9: 8493 | Q9: Chris
A10: 2018 | B10: 3 | C10: 201803 | D10: Kelly Group | E10: 公隆化學股份有限公司 | F10: CPunknow | G10: 專案-未分析顧客 | H10: CustomerProject | I10: 成本累積 | J10: NASL12:電子化學課 | K10: Resource | L10: R05:其他費用 | M10: 16648
A11: 2018 | B11: 3 | C11: 201803 | D11: Kelly Group | E11: 公隆化學股份有限公司 | F11: CPCRM00550 | G11: 專案-瑞興發 | H11: CustomerProject | I11: 成本累積 | J11: NASL11:製程化學課 | K11: Activity | L11: A05:拜訪新客戶 | M11: 1886.3913 | N11: =M11/ActivityCenter!$L$2 -> 48 | Q11: Ian
A12: 2018 | B12: 3 | C12: 201803 | D12: Kelly Group | E12: 公隆化學股份有限公司 | F12: CPCRM00783 | G12: 專案-亞洲漢威 | H12: CustomerProject | I12: 成本累積 | J12: NASL11:製程化學課 | K12: Activity | L12: A05:拜訪新客戶 | M12: 2279.3895 | N12: =M12/ActivityCenter!$L$2 -> 58 | Q12: Ian
A13: 2018 | B13: 3 | C13: 201803 | D13: Kelly Group | E13: 公隆化學股份有限公司 | F13: CPCRM00937 | G13: 專案-大勤化成 | H13: CustomerProject | I13: 成本累積 | J13: NASL11:製程化學課 | K13: Activity | L13: A07:推薦新產品 | M13: 18863.913 | N13: =M13/ActivityCenter!$L$2 -> 480 | Q13: Ian
A14: 2018 | B14: 3 | C14: 201803 | D14: Kelly Group | E14: 公隆化學股份有限公司 | F14: CPCRM01037 | G14: 專案-華邦電 | H14: CustomerProject | I14: 成本累積 | J14: NASL11:製程化學課 | K14: Activity | L14: A09:偕同技術服務 | M14: 8881.7591 | N14: =M14/ActivityCenter!$L$2 -> 226 | Q14: Ian
A15: 2018 | B15: 3 | C15: 201803 | D15: Kelly Group | E15: 公隆化學股份有限公司 | F15: CPCRM01042 | G15: 專案-欣銓科技 | H15: CustomerProject | I15: 成本累積 | J15: NASL11:製程化學課 | K15: Activity | L15: A09:偕同技術服務 | M15: 1650.5924 | N15: =M15/ActivityCenter!$L$2 -> 42 | Q15: Ian
A16: 2018 | B16: 3 | C16: 201803 | D16: Kelly Group | E16: 公隆化學股份有限公司 | F16: CPCRM01042 | G16: 專案-欣銓科技 | H16: CustomerProject | I16: 成本累積 | J16: NASL11:製程化學課 | K16: Activity | L16: A11:取樣分析 | M16: 3694.183 | N16: =M16/ActivityCenter!$L$2 -> 94 | Q16: Ian
A17: 2018 | B17: 3 | C17: 201803 | D17: Kelly Group | E17: 公隆化學股份有限公司 | F17: CPCRM01049 | G17: 專案-台星科 | H17: CustomerProject | I17: 成本累積 | J17: NASL11:製程化學課 | K17: Activity | L17: A09:偕同技術服務 | M17: 5698.4737 | N17: =M17/ActivityCenter!$L$2 -> 145 | Q17: Ian
A18: 2018 | B18: 3 | C18: 201803 | D18: Kelly Group | E18: 公隆化學股份有限公司 | F18: CPCRM01052 | G18: 專案-福懋科技 | H18: CustomerProject | I18: 成本累積 | J18: NASL11:製程化學課 | K18: Activity | L18: A09:偕同技術服務 | M18: 5384.0752 | N18: =M18/ActivityCenter!$L$2 -> 137 | Q18: Ian
A19: 2018 | B19: 3 | C19: 201803 | D19: Kelly Group | E19: 公隆化學股份有限公司 | F19: CPCRM01090 | G19: 專案-台弟工業 | H19: CustomerProject | I19: 成本累積 | J19: NASL11:製程化學課 | K19: Activity | L19: A09:偕同技術服務 | M19: 2633.0879 | N19: =M19/ActivityCenter!$L$2 -> 67 | Q19: Ian
A20: 2018 | B20: 3 | C20: 201803 | D20: Kelly Group | E20: 公隆化學股份有限公司 | F20: CPCRM01091 | G20: 專案-群浤科技 | H20: CustomerProject | I20: 成本累積 | J20: NASL11:製程化學課 | K20: Activity | L20: A09:偕同技術服務 | M20: 4991.077 | N20: =M20/ActivityCenter!$L$2 -> 127 | Q20: Ian
A21: 2018 | B21: 3 | C21: 201803 | D21: Kelly Group | E21: 公隆化學股份有限公司 | F21: CPCRM01091 | G21: 專案-群浤科技 | H21: CustomerProject | I21: 成本累積 | J21: NASL11:製程化學課 | K21: Activity | L21: A11:取樣分析 | M21: 4087.1812 | N21: =M21/ActivityCenter!$L$2 -> 104 | Q21: Ian
A22: 2018 | B22: 3 | C22: 201803 | D22: Kelly Group | E22: 公隆化學股份有限公司 | F22: CPCRM01093 | G22: 專案-巨品表面 | H22: CustomerProject | I22: 成本累積 | J22: NASL11:製程化學課 | K22: Activity | L22: A09:偕同技術服務 | M22: 2515.1884 | N22: =M22/ActivityCenter!$L$2 -> 64 | Q22: Ian
... A44: 2018 | B44: 3 | C44: 201803 | D44: Kelly Group | E44: 公隆化學股份有限公司 | F44: CP other cus | G44: 專案-other customer | H44: CustomerProject | I44: 成本累積 | J44: NASL11:製程化學課 | K44: Activity | L44: A18:Kelly內部事項 | M44: 226366.96 | N44: =M44/ActivityCenter!$L$2 -> 5760 | Q44: Clapton
A45: 2018 | B45: 3 | C45: 201803 | D45: Kelly Group | E45: 公隆化學股份有限公司 | F45: CPCRM10748 | G45: 專案-工研院 | H45: CustomerProject | I45: 成本累積 | J45: NASL12:電子化學課 | K45: Activity | L45: A04:專案追蹤 | M45: 1276.9887 | N45: =M45/ActivityCenter!$L$6 -> 133 | Q45: Louis
A46: 2018 | B46: 3 | C46: 201803 | D46: Kelly Group | E46: 公隆化學股份有限公司 | F46: CPCRM03863 | G46: 專案-致嘉科技 | H46: CustomerProject | I46: 成本累積 | J46: NASL12:電子化學課 | K46: Activity | L46: A05:拜訪新客戶 | M46: 2304.3406 | N46: =M46/ActivityCenter!$L$6 -> 240 | Q46: Chris
A47: 2018 | B47: 3 | C47: 201803 | D47: Kelly Group | E47: 公隆化學股份有限公司 | F47: CPCRM05498 | G47: 專案-興勤電子 | H47: CustomerProject | I47: 成本累積 | J47: NASL12:電子化學課 | K47: Activity | L47: A10:偕同原廠拜訪 | M47: 4608.6812 | N47: =M47/ActivityCenter!$L$6 -> 480 | Q47: Chris
A48: 2018 | B48: 3 | C48: 201803 | D48: Kelly Group | E48: 公隆化學股份有限公司 | F48: CPCRM08397 | G48: 專案-奇美實業 | H48: CustomerProject | I48: 成本累積 | J48: NASL12:電子化學課 | K48: Activity | L48: A03:爭取新專案 | M48: 3072.4541 | N48: =M48/ActivityCenter!$L$6 -> 320 | Q48: Chris
A49: 2018 | B49: 3 | C49: 201803 | D49: Kelly Group | E49: 公隆化學股份有限公司 | F49: CPCRM08411 | G49: 專案-新應材 | H49: CustomerProject | I49: 成本累積 | J49: NASL12:電子化學課 | K49: Activity | L49: A05:拜訪新客戶 | M49: 1344.1987 | N49: =M49/ActivityCenter!$L$6 -> 140 | Q49: Chris
A50: 2018 | B50: 3 | C50: 201803 | D50: Kelly Group | E50: 公隆化學股份有限公司 | F50: CPCRM08720 | G50: 專案-凱耀科技 | H50: CustomerProject | I50: 成本累積 | J50: NASL12:電子化學課 | K50: Activity | L50: A07:推薦新產品 | M50: 1536.2271 | N50: =M50/ActivityCenter!$L$6 -> 160 | Q50: Chris
A51: 2018 | B51: 3 | C51: 201803 | D51: Kelly Group | E51: 公隆化學股份有限公司 | F51: CPCRM10747 | G51: 專案-泓瀚科技 | H51: CustomerProject | I51: 成本累積 | J51: NASL12:電子化學課 | K51: Activity | L51: A04:專案追蹤 | M51: 2304.3406 | N51: =M51/ActivityCenter!$L$6 -> 240 | Q51: Chris
A52: 2018 | B52: 3 | C52: 201803 | D52: Kelly Group | E52: 公隆化學股份有限公司 | F52: CPCRM10771 | G52: 專案-勤凱-浚博 | H52: CustomerProject | I52: 成本累積 | J52: NASL12:電子化學課 | K52: Activity | L52: A10:偕同原廠拜訪 | M52: 2304.3406 | N52: =M52/ActivityCenter!$L$6 -> 240 | Q52: Chris
A53: 2018 | B53: 3 | C53: 201803 | D53: Kelly Group | E53: 公隆化學股份有限公司 | F53: CPCRM10826 | G53: 專案-道登電子 | H53: CustomerProject | I53: 成本累積 | J53: NASL12:電子化學課 | K53: Activity | L53: A10:偕同原廠拜訪 | M53: 2304.3406 | N53: =M53/ActivityCenter!$L$6 -> 240 | Q53: Chris
A54: 2018 | B54: 3 | C54: 201803 | D54: Kelly Group | E54: 公隆化學股份有限公司 | F54: CPCRM10848 | G54: 專案-華新科技 | H54: CustomerProject | I54: 成本累積 | J54: NASL12:電子化學課 | K54: Activity | L54: A09:偕同技術服務 | M54: 1022.5511 | N54: =M54/ActivityCenter!$L$6 -> 106.5 | Q54: Chris
A55: 2018 | B55: 3 | C55: 201803 | D55: Kelly Group | E55: 公隆化學股份有限公司 | F55: CPCRM10848 | G55: 專案-華新科技 | H55: CustomerProject | I55: 成本累積 | J55: NASL12:電子化學課 | K55: Activity | L55: A10:偕同原廠拜訪 | M55: 3326.8917 | N55: =M55/ActivityCenter!$L$6 -> 346.5 | Q55: Chris
A56: 2018 | B56: 3 | C56: 201803 | D56: Kelly Group | E56: 公隆化學股份有限公司 | F56: CPCRM10848 | G56: 專案-華新科技 | H56: CustomerProject | I56: 成本累積 | J56: NASL12:電子化學課 | K56: Activity | L56: A12:客服諮詢 | M56: 4608.6812 | N56: =M56/ActivityCenter!$L$6 -> 480 | Q56: Chris
... A105: 2018 | B105: 3 | C105: 201803 | D105: Kelly Group | E105: 公隆化學股份有限公司 | F105: CP永光二廠 | G105: 專案-永光二廠 | H105: CustomerProject | I105: 成本累積 | J105: NASL12:電子化學課 | K105: Activity | L105: A03:爭取新專案 | M105: 921.73624 | N105: =M105/ActivityCenter!$L$6 -> 96 | Q105: Louis
A106: 2018 | B106: 3 | C106: 201803 | D106: Kelly Group | E106: 公隆化學股份有限公司 | F106: CPCRM05498 | G106: 專案-興勤電子 | H106: CustomerProject | I106: 成本歸屬至產品 | J106: NASL12:電子化學課 | M106: -4608.6812 | O106: 88000428 | P106: 3 | Q106: Chris
A107: 2018 | B107: 3 | C107: 201803 | D107: Kelly Group | E107: 公隆化學股份有限公司 | F107: CPCRM05498 | G107: 專案-興勤電子 | H107: CustomerProject | I107: 成本歸屬至產品 | J107: NASL12:電子化學課 | M107: -1035 | O107: 88000428 | P107: 3 | Q107: Chris
A108: 2018 | B108: 3 | C108: 201803 | D108: Kelly Group | E108: 公隆化學股份有限公司 | F108: CPCRM10771 | G108: 專案-勤凱-浚博 | H108: CustomerProject | I108: 成本歸屬至產品 | J108: NASL12:電子化學課 | M108: -1241.5159 | O108: 88000411 | P108: 17 | Q108: Chris
A109: 2018 | B109: 3 | C109: 201803 | D109: Kelly Group | E109: 公隆化學股份有限公司 | F109: CPCRM10771 | G109: 專案-勤凱-浚博 | H109: CustomerProject | I109: 成本歸屬至產品 | J109: NASL12:電子化學課 | M109: -1062.8247 | O109: 88000413 | P109: 19 | Q109: Chris
...

Sheet 專案成本
B3: Column Labels
B4: 3 | D4: 5 | F4: 4 | H4: Total 加總 - 實際產能(分鐘) | I4: Total 加總 - 金額
A5: Row Labels | B5: 加總 - 實際產能(分鐘) | C5: 加總 - 金額 | D5: 加總 - 實際產能(分鐘) | E5: 加總 - 金額 | F5: 加總 - 實際產能(分鐘) | G5: 加總 - 金額
A6: NASL12:電子化學課 | B6: 13486 | C6: 98299.329 | D6: 10080 | E6: 72182.856 | F6: 8160 | G6: 84526.805 | H6: 31726 | I6: 255008.99
A7: Louis | B7: 6219 | C7: 59711.226 | D7: 3928 | E7: 32495.218 | F7: 4017 | G7: 43377.305 | H7: 14164 | I7: 135583.75
A8: 專案-九怡工業 | D8: 0 | E8: 0 | F8: 159 | G8: -1.1368684e-13 | H8: 159 | I8: -1.1368684e-13
A9: 專案-三德 | D9: 0 | E9: 0 | F9: 82 | G9: 1044.0091 | H9: 82 | I9: 1044.0091 | K9: louis 正在進行的專案有44個
A10: 專案-大格化學 | B10: 194 | C10: 1862.6753 | D10: 180 | E10: 1489.0884 | F10: 0 | G10: 0 | H10: 374 | I10: 3351.7637 | K10: chris 正在進行的專案有41個
A11: 專案-山鶯欣興電子 | B11: 580 | C11: 5568.8231 | D11: 0 | E11: 0 | F11: 0 | G11: 0 | H11: 580 | I11: 5568.8231 | K11: Ian 正在進行的專案有47個
A12: 專案-川裕工業 | B12: 230 | C12: 2208.3264 | D12: 0 | E12: 0 | F12: 0 | G12: 0 | H12: 230 | I12: 2208.3264
A13: 專案-工研院 | B13: 133 | C13: 1276.9887 | D13: 0 | E13: 0 | F13: 384 | G13: 4889.0182 | H13: 517 | I13: 6166.0069
A14: 專案-友輝光電 | B14: 480 | C14: 4608.6812 | D14: 0 | E14: 0 | F14: 0 | G14: 0 | H14: 480 | I14: 4608.6812
A15: 專案-台虹科技 | B15: 160 | C15: 1536.2271 | D15: 0 | E15: 0 | F15: 0 | G15: 0 | H15: 160 | I15: 1536.2271
A16: 專案-台灣同欣 | D16: 0 | E16: 0 | F16: 82 | G16: 0 | H16: 82 | I16: 0
A17: 專案-台灣奈晶 | B17: 465 | C17: 4464.6599 | D17: 0 | E17: 0 | F17: 0 | G17: 0 | H17: 465 | I17: 4464.6599
A18: 專案-台灣-捷能材料 | D18: 5 | E18: 41.363567 | H18: 5 | I18: 41.363567
A19: 專案-台灣優瑪 | D19: 192 | E19: 1588.361 | H19: 192 | I19: 1588.361
A20: 專案-永光二廠 | B20: 96 | C20: 921.73624 | D20: 0 | E20: 0 | F20: 0 | G20: 0 | H20: 96 | I20: 921.73624
A21: 專案-永光三廠 | B21: 192 | C21: 1843.4725 | D21: 0 | E21: 0 | F21: 0 | G21: 0 | H21: 192 | I21: 1843.4725
A22: 專案-永光化學 | D22: 400 | E22: 3309.0854 | F22: 369 | G22: 0 | H22: 769 | I22: 3309.0854
A23: 專案-永明泰 | D23: 0 | E23: 0 | F23: 125 | G23: 1591.4773 | H23: 125 | I23: 1591.4773
A24: 專案-竹北凱鍶 | B24: 160 | C24: 1536.2271 | D24: 0 | E24: 0 | F24: 288 | G24: 3666.7636 | H24: 448 | I24: 5202.9907
A25: 專案-和蓮光電 | D25: 192 | E25: 1588.361 | H25: 192 | I25: 1588.361
A26: 專案-忠信汽車 | D26: 96 | E26: 794.18049 | H26: 96 | I26: 794.18049
A27: 專案-林口南亞科 | B27: 141 | C27: 1353.8001 | D27: 0 | E27: 0 | F27: 0 | G27: 0 | H27: 141 | I27: 1353.8001
A28: 專案-林口穩懋 | B28: 45 | C28: 432.06386 | D28: 160 | E28: 1323.6341 | F28: 0 | G28: 0 | H28: 205 | I28: 1755.698
A29: 專案-矽恩特殊材料 | B29: 190 | C29: 1824.2696 | D29: 0 | E29: 0 | F29: 214 | G29: 2724.6091 | H29: 404 | I29: 4548.8787
A30: 專案-肥特補 | D30: 0 | E30: 0 | F30: 221 | G30: 2813.7318 | H30: 221 | I30: 2813.7318
A31: 專案-金順億 | D31: 120 | E31: 992.72561 | H31: 120 | I31: 992.72561
A32: 專案-長春-乾膜 | B32: 78 | C32: 748.91069 | D32: 440 | E32: 3639.9939 | F32: 258 | G32: 3284.8091 | H32: 776 | I32: 7673.7137
A33: 專案-洤順科技 | B33: 246 | C33: 2361.9491 | D33: 0 | E33: 0 | F33: 0 | G33: 0 | H33: 246 | I33: 2361.9491
A34: 專案-桃園-宸鴻 | B34: 206 | C34: 1977.8923 | D34: 160 | E34: 1323.6341 | F34: 0 | G34: 0 | H34: 366 | I34: 3301.5265
A35: 專案-創毅國際 | B35: 281 | C35: 2697.9988 | D35: 0 | E35: 0 | F35: 0 | G35: 0 | H35: 281 | I35: 2697.9988
A36: 專案-晶呈科技 | D36: 192 | E36: 1588.361 | H36: 192 | I36: 1588.361
A37: 專案-微鑽石 | D37: 0 | E37: 0 | F37: 123 | G37: 1566.0136 | H37: 123 | I37: 1566.0136
A38: 專案-愛迪克 | B38: 15 | C38: 144.02129 | D38: 0 | E38: 0 | F38: 0 | G38: 0 | H38: 15 | I38: 144.02129
A39: 專案-新北市-富致科技 | D39: 192 | E39: 1588.361 | F39: 165 | G39: 2100.75 | H39: 357 | I39: 3689.111
A40: 專案-新竹互力 | B40: 214 | C40: 2054.7037 | D40: 259 | E40: 2142.6328 | F40: 0 | G40: 0 | H40: 473 | I40: 4197.3365
A41: 專案-新竹光聚合 | B41: 133 | C41: 1276.9887 | D41: 240 | E41: 1985.4512 | F41: 222 | G41: 2826.4636 | H41: 595 | I41: 6088.9036
A42: 專案-瑞化 | B42: 95 | C42: 912.13482 | D42: 0 | E42: 0 | F42: 0 | G42: 0 | H42: 95 | I42: 912.13482
...

Sheet IncomeStatment
A1: 年 | B1: 月份 | C1: 公司代碼 | D1: 作業中心代碼 | E1: 訂單編號 | F1: 產品 | G1: 數量 | H1: 金額 | I1: 總銷貨成本 | J1: 製造成本 | K1: 客戶利潤 | L1: 產品利潤 | M1: 業務工程師
A2: 2018 | B2: 3 | C2: Kelly Group | D2: NASL12 | E2: Order01 | F2: 87000189 | G2: 72 | H2: 30600 | I2: 14564 | J2: 14564 | K2: 16036 | L2: 16036 | M2: Louis
A3: 2018 | B3: 3 | C3: Kelly Group | D3: NASL11 | E3: Order02 | F3: 74000242 | G3: 36 | H3: 16200 | I3: 13292 | J3: 13292 | K3: 2908 | L3: 2908 | M3: Vincent
A4: 2018 | B4: 3 | C4: Kelly Group | D4: NASL11 | E4: Order03 | F4: 74000158 | G4: 428 | H4: 74900 | I4: 44091 | J4: 44091 | K4: 30809 | L4: 30809 | M4: Vincent
A5: 2018 | B5: 3 | C5: Kelly Group | D5: NASL11 | E5: Order04 | F5: 74000063 | G5: 20 | H5: 9600 | I5: 4592 | J5: 4592 | K5: 5008 | L5: 5008 | M5: Vincent
A6: 2018 | B6: 3 | C6: Kelly Group | D6: NASL11 | E6: Order05 | F6: 71000576 | G6: 20 | H6: 6400 | I6: 2637 | J6: 2637 | K6: 3763 | L6: 3763 | M6: Vincent
A7: 2018 | B7: 3 | C7: Kelly Group | D7: NASL11 | E7: Order06 | F7: 74000162 | G7: 1000 | H7: 125000 | I7: 71469 | J7: 71469 | K7: 53531 | L7: 53531 | M7: Vincent
A8: 2018 | B8: 3 | C8: Kelly Group | D8: NASL12 | E8: Order07 | F8: 88000513 | G8: 16 | H8: 15360 | I8: 0 | K8: 15360 | L8: 15360 | M8: Chris
A9: 2018 | B9: 3 | C9: Kelly Group | D9: NASL12 | E9: Order07 | F9: 88000513 | G9: 16 | H9: 15360 | I9: 5248 | J9: 5248 | K9: 10112 | L9: 10112 | M9: Chris
A10: 2018 | B10: 3 | C10: Kelly Group | D10: NASL11 | E10: Order08 | F10: 74000193 | G10: 415.6 | H10: 60000 | I10: 33664 | J10: 33664 | K10: 26336 | L10: 26336 | M10: Vincent
A11: 2018 | B11: 3 | C11: Kelly Group | D11: NASL12 | E11: Order09 | F11: 87000182 | G11: 45 | H11: 60210 | I11: 40292 | J11: 40292 | K11: 19918 | L11: 19918 | M11: Chris
A12: 2018 | B12: 3 | C12: Kelly Group | D12: NASL12 | E12: Order10 | F12: 87000175 | G12: 26 | H12: 27066 | I12: 18538 | J12: 18538 | K12: 8528 | L12: 8528 | M12: Chris
A13: 2018 | B13: 3 | C13: Kelly Group | D13: NASL11 | E13: Order11 | F13: 74000254 | G13: 260 | H13: 52000 | I13: 36400 | J13: 36400 | K13: 15600 | L13: 15600 | M13: Vincent
A14: 2018 | B14: 3 | C14: Kelly Group | D14: NASL12 | E14: Order12 | F14: 88000426 | G14: 18 | H14: 68400 | I14: 0 | K14: 68400 | L14: 68400 | M14: Chris
A15: 2018 | B15: 3 | C15: Kelly Group | D15: NASL12 | E15: Order12 | F15: 88000426 | G15: 18 | H15: 68400 | I15: 26595.333 | J15: 26595.333 | K15: 41804.667 | L15: 41804.667 | M15: Chris
A16: 2018 | B16: 3 | C16: Kelly Group | D16: NASL12 | E16: Order13 | F16: 88000423 | G16: 17 | H16: 37400 | I16: 0 | K16: 37400 | L16: 37400 | M16: Chris
A17: 2018 | B17: 3 | C17: Kelly Group | D17: NASL12 | E17: Order13 | F17: 88000423 | G17: 17 | H17: 37400 | I17: 18687 | J17: 18687 | K17: 18713 | L17: 18713 | M17: Chris
A18: 2018 | B18: 3 | C18: Kelly Group | D18: NASL12 | E18: Order14 | F18: 87000085 | G18: 17 | H18: 30600 | I18: 0 | K18: 30600 | L18: 30600 | M18: Chris
A19: 2018 | B19: 3 | C19: Kelly Group | D19: NASL12 | E19: Order14 | F19: 87000085 | G19: 17 | H19: 30600 | I19: 21134 | J19: 21134 | K19: 9466 | L19: 9466 | M19: Chris
A20: 2018 | B20: 3 | C20: Kelly Group | D20: NASL12 | E20: Order15 | F20: 88000407 | G20: 34 | H20: 36550 | I20: 0 | K20: 36550 | L20: 36550 | M20: Chris
A21: 2018 | B21: 3 | C21: Kelly Group | D21: NASL12 | E21: Order15 | F21: 88000407 | G21: 34 | H21: 36550 | I21: 20094.182 | J21: 20094.182 | K21: 16455.818 | L21: 16455.818 | M21: Chris
A22: 2018 | B22: 3 | C22: Kelly Group | D22: NASL12 | E22: Order16 | F22: 88000426 | G22: 36 | H22: 118800 | I22: 0 | K22: 118800 | L22: 118800 | M22: Chris
A23: 2018 | B23: 3 | C23: Kelly Group | D23: NASL12 | E23: Order16 | F23: 88000426 | G23: 36 | H23: 118800 | I23: 53190.667 | J23: 53190.667 | K23: 65609.333 | L23: 65609.333 | M23: Chris
A24: 2018 | B24: 3 | C24: Kelly Group | D24: NASL12 | E24: Order17 | F24: 88000407 | G24: 153 | H24: 164475 | I24: 0 | K24: 164475 | L24: 164475 | M24: Chris
A25: 2018 | B25: 3 | C25: Kelly Group | D25: NASL12 | E25: Order17 | F25: 88000407 | G25: 153 | H25: 164475 | I25: 90423.818 | J25: 90423.818 | K25: 74051.182 | L25: 74051.182 | M25: Chris
A26: 2018 | B26: 3 | C26: Kelly Group | D26: NASL11 | E26: Order18 | F26: 61000027 | G26: 120 | H26: 21000 | I26: 4663.9999 | J26: 4663.9999 | K26: 16336 | L26: 16336 | M26: Ian
A27: 2018 | B27: 3 | C27: Kelly Group | D27: NASL11 | E27: Order19 | F27: 61000017 | G27: 300 | H27: 43500 | I27: 25265 | J27: 25265 | K27: 18235 | L27: 18235 | M27: Ian
A28: 2018 | B28: 3 | C28: Kelly Group | D28: NASL12 | E28: Order20 | F28: 88000411 | G28: 17 | H28: 79900 | I28: 0 | K28: 79900 | L28: 79900 | M28: Chris
A29: 2018 | B29: 3 | C29: Kelly Group | D29: NASL12 | E29: Order20 | F29: 88000411 | G29: 17 | H29: 79900 | I29: 32759 | J29: 32759 | K29: 47141 | L29: 47141 | M29: Chris
A30: 2018 | B30: 3 | C30: Kelly Group | D30: NASL12 | E30: Order21 | F30: 88000413 | G30: 19 | H30: 68400 | I30: 0 | K30: 68400 | L30: 68400 | M30: Chris
A31: 2018 | B31: 3 | C31: Kelly Group | D31: NASL12 | E31: Order21 | F31: 88000413 | G31: 19 | H31: 68400 | I31: 42109 | J31: 42109 | K31: 26291 | L31: 26291 | M31: Chris
A32: 2018 | B32: 3 | C32: Kelly Group | D32: NASL11 | E32: Order22 | F32: 74000245 | G32: 750 | H32: 187500 | I32: 114000 | J32: 114000 | K32: 73500 | L32: 73500 | M32: Vincent
A33: 2018 | B33: 3 | C33: Kelly Group | D33: NASL11 | E33: Order23 | F33: 74000245 | G33: 500 | H33: 125000 | I33: 76000 | J33: 76000 | K33: 49000 | L33: 49000 | M33: Vincent
A34: 2018 | B34: 3 | C34: Kelly Group | D34: NASL11 | E34: Order24 | F34: 74000071 | G34: 20 | H34: 4500 | I34: 2420.6667 | J34: 2420.6667 | K34: 2079.3333 | L34: 2079.3333 | M34: Vincent
A35: 2018 | B35: 3 | C35: Kelly Group | D35: NASL11 | E35: Order25 | F35: 74000071 | G35: 40 | H35: 9000 | I35: 4841.3333 | J35: 4841.3333 | K35: 4158.6667 | L35: 4158.6667 | M35: Vincent
A36: 2018 | B36: 3 | C36: Kelly Group | D36: NASL11 | E36: Order26 | F36: 74000252 | G36: 90 | H36: 38250 | I36: 27815 | J36: 27815 | K36: 10435 | L36: 10435 | M36: Vincent
A37: 2018 | B37: 3 | C37: Kelly Group | D37: NASL12 | E37: Order27 | F37: 88000428 | G37: 3 | H37: 24600 | I37: 0 | K37: 24600 | L37: 24600 | M37: Chris
A38: 2018 | B38: 3 | C38: Kelly Group | D38: NASL12 | E38: Order27 | F38: 88000428 | G38: 3 | H38: 24600 | I38: 9741 | J38: 9741 | K38: 14859 | L38: 14859 | M38: Chris
A39: 2018 | B39: 3 | C39: Kelly Group | D39: NASL12 | E39: Order28 | F39: 88000535 | G39: 16 | H39: 14400 | I39: 5896 | J39: 5896 | K39: 8504 | L39: 8504 | M39: Chris
A40: 2018 | B40: 3 | C40: Kelly Group | D40: NASL12 | E40: Order29 | F40: 88000554 | G40: 15 | H40: 12750 | I40: 6649 | J40: 6649 | K40: 6101 | L40: 6101 | M40: Chris
...

Sheet CustomerProfitResult
A1: 年 | B1: 月份 | C1: 期間資料版本 | D1: 公司 | E1: 事業單位 | F1: 顧客代碼 | G1: 顧客 | H1: 銷貨收入 | I1: 製造成本 | J1: 銷貨毛利 | K1: 銷貨作業成本 | L1: 資源直歸客戶成本 | M1: 總銷貨成本 | N1: 客戶利潤 | O1: 客戶利潤率
A2: 2018 | B2: 3 | C2: 201803 | D2: Kelly Group | E2: 公隆化學股份有限公司 | F2: CRM00024 | G2: 亞洲光學 | H2: 16000 | I2: 7229 | J2: 8771 | K2: 0 | L2: 0 | M2: 7229 | N2: 8771 | O2: 0.548187
A3: 2018 | B3: 3 | C3: 201803 | D3: Kelly Group | E3: 公隆化學股份有限公司 | F3: CRM00400 | G3: 東隆五金 | H3: 125000 | I3: 71469 | J3: 53531 | K3: 0 | L3: 0 | M3: 71469 | N3: 53531 | O3: 0.428248
A4: 2018 | B4: 3 | C4: 201803 | D4: Kelly Group | E4: 公隆化學股份有限公司 | F4: CRM00432 | G4: 佳能 | H4: 16200 | I4: 13292 | J4: 2908 | K4: 0 | L4: 0 | M4: 13292 | N4: 2908 | O4: 0.179506
A5: 2018 | B5: 3 | C5: 201803 | D5: Kelly Group | E5: 公隆化學股份有限公司 | F5: CRM00478 | G5: 億豐(代買士林電機) | H5: 38250 | I5: 27815 | J5: 10435 | K5: 0 | L5: 0 | M5: 27815 | N5: 10435 | O5: 0.27281
A6: 2018 | B6: 3 | C6: 201803 | D6: Kelly Group | E6: 公隆化學股份有限公司 | F6: CRM00696 | G6: 健達生物 | H6: 52000 | I6: 36400 | J6: 15600 | K6: 0 | L6: 0 | M6: 36400 | N6: 15600 | O6: 0.3
A7: 2018 | B7: 3 | C7: 201803 | D7: Kelly Group | E7: 公隆化學股份有限公司 | F7: CRM00860 | G7: 茂順 | H7: 60000 | I7: 33664 | J7: 26336 | K7: 0 | L7: 0 | M7: 33664 | N7: 26336 | O7: 0.438933
A8: 2018 | B8: 3 | C8: 201803 | D8: Kelly Group | E8: 公隆化學股份有限公司 | F8: CRM00888 | G8: 中壢億達薄膜 | H8: 13500 | I8: 7262 | J8: 6238 | K8: 0 | L8: 0 | M8: 7262 | N8: 6238 | O8: 0.462074
A9: 2018 | B9: 3 | C9: 201803 | D9: Kelly Group | E9: 公隆化學股份有限公司 | F9: CRM00911 | G9: 台灣鉅邁 | H9: 74900 | I9: 44091 | J9: 30809 | K9: 0 | L9: 0 | M9: 44091 | N9: 30809 | O9: 0.411335
A10: 2018 | B10: 3 | C10: 201803 | D10: Kelly Group | E10: 公隆化學股份有限公司 | F10: CRM00933 | G10: 榮助 | H10: 312500 | I10: 190000 | J10: 122500 | K10: 0 | L10: 0 | M10: 190000 | N10: 122500 | O10: 0.392
A11: 2018 | B11: 3 | C11: 201803 | D11: Kelly Group | E11: 公隆化學股份有限公司 | F11: CRM01025 | G11: 典雅實業 | H11: 76800 | I11: 15966 | J11: 60834 | K11: 0 | L11: 0 | M11: 15966 | N11: 60834 | O11: 0.792109
A12: 2018 | B12: 3 | C12: 201803 | D12: Kelly Group | E12: 公隆化學股份有限公司 | F12: CRM05197 | G12: 聯致科技 | H12: 39900 | I12: 19194 | J12: 20706 | K12: 0 | L12: 0 | M12: 19194 | N12: 20706 | O12: 0.518947
A13: 2018 | B13: 3 | C13: 201803 | D13: Kelly Group | E13: 公隆化學股份有限公司 | F13: CRM05498 | G13: 興勤電子 | H13: 24600 | I13: 9741 | J13: 14859 | K13: 0 | L13: 0 | M13: 9741 | N13: 14859 | O13: 0.604024
... A66: 2018 | B66: 5 | C66: 201805 | D66: Kelly Group | E66: 公隆化學股份有限公司 | F66: 華震科技 | G66: 華震科技 | H66: 122250 | I66: 44489.617 | J66: 77760.383 | K66: 0 | L66: 0 | M66: 44489.617 | N66: 77760.383 | O66: 0.636076

Sheet ProductProfitResult
